Workbook

Sheet K&L 지게차 Master list
F1: 지게차 보유 현황 List _ 2025. 04월 17일 현재
A3: No. | B3: K&L 등록 | C3: 제조 | D3: 동력 | E3: 종류 | F3: 장비 No | G3: 사업장 | H3: 계약처 | I3: 상태 | J3: 담당자 | K3: 배치장소 | L3: 배치No | M3: 운영 | N3: 규격 | O3: 톤수 | P3: 제작처 | Q3: 모델명 | R3: 차대번호 | S3: 년식 | T3: 가동 시간 | U3: 차량 등록 No. | V3: 보험 | W3: 보함사 | X3: 계약자 | Y3: 피보험자 | Z3: 자산처 | AA3: 자산 등록일 | AB3: 임대 시작일 | AC3: 임대료 | AD3: 차량가액
A4: 1 | B4: =MID(F4,8,3) -> 001 | C4: =MID(F4,1,1) -> C | D4: =MID(F4,3,1) -> B | E4: =MID(F4,2,1) -> F | F4: CFB30-0001 | G4: 범한_항성 | H4: 범한_항성 | I4: 임대 | J4: 고민서 | K4: 범한메카텍_항성 | L4: 항성-01 | M4: 주간 | N4: 좌식 | O4: 3.0T | P4: 클라크 | Q4: EPX30 | R4: EPX360 2302 9652 KF | S4: 39448 | T4: 23716 | V4: Y | W4: KB | X4: 케이앤엘 | Y4: (주)항성 | Z4: 케이앤엘 | AA4: 43313 | AB4: 45383 | AC4: 600000 | AD4: 18500000
A5: 2 | B5: =MID(F5,8,3) -> 002 | C5: =MID(F5,1,1) -> C | D5: =MID(F5,3,1) -> B | E5: =MID(F5,2,1) -> F | F5: CFB25-0002 | G5: 포엠플러스 | H5: 포엠플러스 | I5: 임대 | J5: 이승희 | L5: 포엠- 02 | M5: 주간 | N5: 좌식 | O5: 2.5T | P5: 클라크 | Q5: EPX25FL | R5: EPX360-0310-9959KF | S5: 42005 | T5: 0 | V5: N | Z5: 케이앤엘 | AA5: 43647 | AB5: 43647 | AC5: 500000 | AD5: 10000000
A6: 3 | B6: =MID(F6,8,3) -> 003 | C6: =MID(F6,1,1) -> D | D6: =MID(F6,3,1) -> O | E6: =MID(F6,2,1) -> F | F6: DFO30-0003 | G6: ZF삭스 | H6: 엘소 | I6: 임대 | J6: 이상용 | L6: ZF삭스-03 | M6: 주간 | N6: 좌식 | O6: 3.0T | P6: 두산 | Q6: D30SE-7 | R6: FDA0R-2340-06907 | S6: 43313 | T6: 0 | U6: 경남 04노 8341 | V6: Y | W6: KB | X6: 엘소 | Y6: ㈜엘소 | Z6: 엘소 | AA6: 43318 | AB6: 43318 | AC6: 776000 | AD6: 31490000
A7: 4 | B7: =MID(F7,8,3) -> 004 | C7: =MID(F7,1,1) -> D | D7: =MID(F7,3,1) -> O | E7: =MID(F7,2,1) -> F | F7: DFO30-0004 | G7: (주)대동 | H7: 청운 | I7: 임대 | J7: 이병대 | K7: 대구 달성공장 | L7: 대동-04 | M7: 주간 | N7: 좌식 | O7: 3.0T | P7: 두산 | Q7: D30S-7 | R7: FDA0W-2340-02154 | S7: 42955 | T7: 7815 | U7: 경남 04노 7874 | V7: Y | W7: KB | X7: 케이앤엘 | Y7: ㈜청운 | Z7: 케이앤엘 | AA7: 43831 | AB7: 45614 | AC7: 900000 | AD7: 20000000
A8: 5 | B8: =MID(F8,8,3) -> 005 | C8: =MID(F8,1,1) -> D | D8: =MID(F8,3,1) -> B | E8: =MID(F8,2,1) -> F | F8: DFB20-0005 | G8: ZF삭스 | H8: 엘소 | I8: 임대 | J8: 이상용 | L8: ZF삭스-05 | M8: 주간 | N8: 좌식 | O8: 2.0T | P8: 두산 | Q8: B20S-5 | R8: FBA07-1380-00856 | S8: 40909 | T8: 0 | V8: Y | W8: KB | X8: 엘소 | Y8: ㈜엘소 | Z8: 엘소 | AA8: 43831 | AB8: 43831 | AC8: 756600 | AD8: 18000000
A9: 6 | B9: =MID(F9,8,3) -> 006 | C9: =MID(F9,1,1) -> C | D9: =MID(F9,3,1) -> B | E9: =MID(F9,2,1) -> F | F9: CFB18-0006 | G9: 케이앤엘 | I9: 예비 | J9: 이승희 | K9: 지게차 창고 | L9: 예비-06 | M9: 주간 | N9: 좌식 | O9: 1.8T | P9: 클라크 | Q9: EPX18 | R9: EPX162-0965-9818KF | S9: 40909 | T9: 0 | V9: N | Z9: 케이앤엘 | AA9: 43831 | AB9: 45383 | AC9: 0 | AD9: 18000000
A10: 7 | B10: =MID(F10,8,3) -> 007 | C10: =MID(F10,1,1) -> D | D10: =MID(F10,3,1) -> B | E10: =MID(F10,2,1) -> F | F10: DFB20-0007 | G10: ZF삭스 | H10: 엘소 | I10: 임대 | J10: 이상용 | L10: ZF삭스-07 | M10: 주간 | N10: 좌식 | O10: 2.0T | P10: 두산 | Q10: B20S-5 | R10: FBA07-1910-01817 | S10: 42887 | T10: 0 | V10: Y | W10: KB | X10: 엘소 | Y10: ㈜엘소 | Z10: 엘소 | AA10: 43831 | AB10: 43831 | AC10: 756600 | AD10: 8500000
A11: 8 | B11: =MID(F11,8,3) -> 008 | C11: =MID(F11,1,1) -> C | D11: =MID(F11,3,1) -> B | E11: =MID(F11,2,1) -> F | F11: CFB18-0008 | G11: ZF삭스 | H11: 엘소 | I11: 임대 | J11: 이상용 | L11: ZF삭스-08 | M11: 주간 | N11: 좌식 | O11: 1.8T | P11: 클라크 | Q11: EPX18 | R11: EPX162-0962-9818KF | S11: 40909 | T11: 0 | V11: Y | W11: KB | X11: 엘소 | Y11: ㈜엘소 | Z11: 엘소 | AA11: 43831 | AB11: 43831 | AC11: 756600 | AD11: 8500000
A12: 9 | B12: =MID(F12,8,3) -> 009 | C12: =MID(F12,1,1) -> D | D12: =MID(F12,3,1) -> O | E12: =MID(F12,2,1) -> F | F12: DFO30-0009 | G12: ZF삭스 | H12: 엘소 | I12: 임대 | J12: 이상용 | L12: ZF삭스-09 | M12: 주간 | N12: 좌식 | O12: 3.0T | P12: 두산 | Q12: D30S-7 | R12: FDA0W-2340-02155 | S12: 42887 | T12: 0 | U12: 경남 04노 7875 | V12: Y | W12: KB | X12: 엘소 | Y12: ㈜엘소 | Z12: 엘소 | AA12: 43831 | AB12: 43831 | AC12: 747000 | AD12: 10500000
A13: 10 | B13: =MID(F13,8,3) -> 010 | C13: =MID(F13,1,1) -> D | D13: =MID(F13,3,1) -> O | E13: =MID(F13,2,1) -> F | F13: DFO30-0010 | G13: 디와이파워 | H13: 디와이파워 | I13: 임대 | J13: 이승희 | K13: 디와이파워 | L13: 2Y-3 | M13: 주간 | N13: 좌식 | O13: 3.0T | P13: 두산 | Q13: D30S-7 | R13: FDA0W-2340-02156 | S13: 42887 | T13: 0 | U13: 경남 04노 7876 | V13: Y | W13: KB | X13: 케이앤엘 | Y13: ㈜케이앤엘 | Z13: 케이앤엘 | AA13: 43831 | AB13: 45108 | AC13: 600000 | AD13: 17000000
A14: 11 | B14: =MID(F14,8,3) -> 011 | C14: =MID(F14,1,1) -> D | D14: =MID(F14,3,1) -> B | E14: =MID(F14,2,1) -> F | F14: DFB18-0011 | G14: ZF삭스 | H14: 엘소 | I14: 임대 | J14: 이상용 | L14: ZF삭스-11 | M14: 주간 | N14: 입식 | O14: 1.8T | P14: 두산 | Q14: BR18S-9 | R14: FRA0T-1380-00458 | S14: 44470 | T14: 0 | V14: Y | W14: KB | X14: 엘소 | Y14: (주)제트에프삭스코 | Z14: 엘소 | AA14: 44490 | AB14: 44490 | AC14: 670000 | AD14: 23500000
A15: 12 | B15: =MID(F15,8,3) -> 012 | C15: =MID(F15,1,1) -> D | D15: =MID(F15,3,1) -> O | E15: =MID(F15,2,1) -> F | F15: DFO30-0012 | G15: 디와이파워 | H15: 디와이파워 | I15: 임대 | J15: 이승희 | K15: 디와이파워-2공장 | L15: 2Y-4 | M15: 주간 | N15: 좌식 | O15: 3.0T | P15: 두산 | Q15: D30S-5 | R15: FDA06-1000-11364 | S15: 40544 | T15: 0 | U15: 경남 04노5178 | V15: Y | W15: KB | X15: 케이앤엘 | Y15: 케이앤엘 | Z15: 케이앤엘 | AA15: 42552 | AB15: 45108 | AC15: 650000 | AD15: 10000000
A16: 13 | B16: =MID(F16,8,3) -> 013 | C16: =MID(F16,1,1) -> C | D16: =MID(F16,3,1) -> B | E16: =MID(F16,2,1) -> F | F16: CFB18-0013 | G16: ZF삭스 | H16: 엘소 | I16: 임대 | J16: 이상용 | L16: ZF삭스-13 | M16: 주간 | N16: 좌식 | O16: 1.8T | P16: 클라크 | Q16: EPX18FL | R16: EPX162-1035-9958KT | S16: 42887 | T16: 0 | V16: Y | W16: KB | X16: 엘소 | Y16: ㈜엘소 | Z16: 엘소 | AA16: 43831 | AB16: 43831 | AC16: 776000 | AD16: 11000000
A17: 14 | B17: =MID(F17,8,3) -> 014 | C17: =MID(F17,1,1) -> C | D17: =MID(F17,3,1) -> B | E17: =MID(F17,2,1) -> F | F17: CFB18-0014 | G17: ZF삭스 | H17: 엘소 | I17: 임대 | J17: 이상용 | K17: ZF삭스 | L17: ZF삭스-14 | M17: 주간 | N17: 좌식 | O17: 1.8T | P17: 클라크 | Q17: EPX16 | R17: EPX162-0340-9651KF | S17: 39083 | T17: 0 | V17: Y | W17: KB | X17: 엘소 | Y17: ㈜엘소 | Z17: 엘소 | AA17: 43831 | AB17: 45383 | AC17: 756600 | AD17: 5000000
A18: 15 | B18: =MID(F18,8,3) -> 015 | C18: =MID(F18,1,1) -> C | D18: =MID(F18,3,1) -> B | E18: =MID(F18,2,1) -> F | F18: CFB20-0015 | G18: ZF삭스 | H18: 엘소 | I18: 임대 | J18: 이상용 | L18: ZF삭스-15 | M18: 주간 | N18: 좌식 | O18: 2.0T | P18: 클라크 | Q18: EPX20SFL | R18: EPX162-3113-9958KF | S18: 44378 | T18: 0 | V18: Y | W18: KB | X18: 엘소 | Y18: (주)엘소 | Z18: 엘소 | AA18: 44409 | AB18: 44409 | AC18: 776000 | AD18: 28000000
A19: 16 | B19: =MID(F19,8,3) -> 016 | C19: =MID(F19,1,1) -> C | D19: =MID(F19,3,1) -> B | E19: =MID(F19,2,1) -> F | F19: CFB18-0016 | G19: 베스텍 | H19: 베스텍 | I19: 임대 | J19: 고민서 | K19: 베스텍 | L19: 베스텍-16 | M19: 주간 | N19: 입식 | O19: 1.8T | P19: 클라크 | Q19: CRX18FL | R19: CRX148-0797-9956KF | S19: 42736 | T19: 0 | V19: N | Z19: 케이앤엘 | AA19: 42736 | AB19: 45597 | AC19: 450000 | AD19: 18600000
A20: 17 | B20: =MID(F20,8,3) -> 017 | C20: =MID(F20,1,1) -> C | D20: =MID(F20,3,1) -> B | E20: =MID(F20,2,1) -> F | F20: CFB18-0017 | G20: ZF삭스 | H20: 엘소 | I20: 임대 | J20: 이상용 | L20: ZF삭스-17 | M20: 주간 | N20: 입식 | O20: 1.8T | P20: 클라크 | Q20: CRX18FL | R20: CRX148-0948-9956KF | S20: 42795 | T20: 0 | V20: Y | W20: KB | X20: 엘소 | Y20: (주)엘소 | Z20: 엘소 | AA20: 42795 | AB20: 42795 | AC20: 582000 | AD20: 12920000
A21: 18 | B21: =MID(F21,8,3) -> 018 | C21: =MID(F21,1,1) -> C | D21: =MID(F21,3,1) -> B | E21: =MID(F21,2,1) -> F | F21: CFB18-0018 | G21: ZF삭스 | H21: 엘소 | I21: 임대 | J21: 이상용 | L21: ZF삭스-18 | M21: 주간 | N21: 입식 | O21: 1.8T | P21: 클라크 | Q21: CRX18FL | R21: CRX148-2936-9956KF | S21: 44228 | T21: 0 | V21: Y | W21: KB | X21: 엘소 | Y21: (주)다윈즈 | Z21: 엘소 | AA21: 44243 | AB21: 44243 | AC21: 630000 | AD21: 8500000
A22: 19 | B22: =MID(F22,8,3) -> 019 | C22: =MID(F22,1,1) -> C | D22: =MID(F22,3,1) -> B | E22: =MID(F22,2,1) -> F | F22: CFB18-0019 | G22: 케이앤엘 | I22: 예비 | J22: 이승희 | K22: 지게차 창고 | L22: 예비-19 | M22: 주간 | N22: 좌식 | O22: 1.8T | P22: 클라크 | Q22: EPX18 | R22: EPX162-0967-9818KF | S22: 40909 | T22: 0 | V22: N | Z22: 케이앤엘 | AA22: 44013 | AB22: 45413 | AC22: 0 | AD22: 8500000
A23: 20 | B23: =MID(F23,8,3) -> 020 | C23: =MID(F23,1,1) -> C | D23: =MID(F23,3,1) -> B | E23: =MID(F23,2,1) -> T | F23: CTB40-0020 | G23: ZF삭스 | H23: 엘소 | I23: 임대 | J23: 이상용 | L23: ZF삭스-20 | M23: 주간 | N23: 견인 | O23: 4.0T | P23: 클라크 | R23: CTX470-0439-9812KF | S23: 42064 | T23: 0 | V23: N | Z23: 엘소 | AA23: 42095 | AB23: 42095 | AC23: 388000 | AD23: 19200000
A24: 21 | B24: =MID(F24,8,3) -> 021 | C24: =MID(F24,1,1) -> C | D24: =MID(F24,3,1) -> B | E24: =MID(F24,2,1) -> T | F24: CTB40-0021 | G24: ZF삭스 | H24: 엘소 | I24: 임대 | J24: 이상용 | L24: ZF삭스-21 | M24: 주간 | N24: 견인 | O24: 4.0T | P24: 클라크 | R24: CTX470-0902-9812KF | S24: 44105 | T24: 0 | V24: N | Z24: 엘소 | AA24: 44105 | AB24: 44105 | AC24: 400000 | AD24: 28000000
A25: 22 | B25: =MID(F25,8,3) -> 022 | C25: =MID(F25,1,1) -> T | D25: =MID(F25,3,1) -> B | E25: =MID(F25,2,1) -> F | F25: TFB25-0022 | G25: 대신 마산공장 | H25: 대신 마산공장 | I25: 임대 | J25: 이승희 | K25: 1공장-1층(용해) | L25: 대신-마산-22 | M25: 주간 | N25: 좌식 | O25: 2.5T | P25: 도요다 | R25: 7FB25-49549 V3 | S25: 41275 | T25: 0 | V25: N | Z25: 케이앤엘 | AA25: 43282 | AB25: 43282 | AC25: 500000 | AD25: 19800000
A26: 23 | B26: =MID(F26,8,3) -> 023 | C26: =MID(F26,1,1) -> T | D26: =MID(F26,3,1) -> B | E26: =MID(F26,2,1) -> F | F26: TFB15-0023 | G26: 대신 마산공장 | H26: 대신 마산공장 | I26: 임대 | J26: 이승희 | K26: 1공장-1층 | L26: 대신-마산-23 | M26: 주간 | N26: 입식 | O26: 1.5T | P26: 도요다 | R26: 7FBR15-21135 | S26: 38718 | T26: 0 | V26: N | Z26: 케이앤엘 | AA26: 43282 | AB26: 43282 | AC26: 350000 | AD26: 4421000
A27: 24 | B27: =MID(F27,8,3) -> 024 | C27: =MID(F27,1,1) -> T | D27: =MID(F27,3,1) -> B | E27: =MID(F27,2,1) -> F | F27: TFB25-0024 | G27: 신흥철재코리아 주식회사 | I27: 매각 | J27: 고민서 | K27: 폐기 | L27: 폐기 | M27: 주간 | N27: 좌식 | O27: 2.5T | P27: 도요다 | R27: 7FB25-49792 V3 | S27: 41275 | T27: 0 | V27: N | Z27: 케이앤엘 | AA27: 43282 | AB27: 45909 | AC27: 0 | AD27: 19700000
A28: 25 | B28: =MID(F28,8,3) -> 025 | C28: =MID(F28,1,1) -> T | D28: =MID(F28,3,1) -> B | E28: =MID(F28,2,1) -> F | F28: TFB10-0025 | G28: 대신 마산공장 | H28: 대신 마산공장 | I28: 임대 | J28: 이승희 | K28: 1공장-3층 | L28: 대신-마산-25 | M28: 주간 | N28: 입식 | O28: 1.0T | P28: 도요다 | R28: 7FBRK9-11473 V2.5 | S28: 38718 | T28: 0 | V28: N | Z28: 케이앤엘 | AA28: 43282 | AB28: 43282 | AC28: 350000 | AD28: 3300000
A29: 26 | B29: =MID(F29,8,3) -> 026 | C29: =MID(F29,1,1) -> C | D29: =MID(F29,3,1) -> B | E29: =MID(F29,2,1) -> F | F29: CFB30-0026 | G29: 대신 마산공장 | H29: 대신 마산공장 | I29: 임대 | J29: 이승희 | K29: 2공장-열처리 | L29: 대신-마산-26 | M29: 주간 | N29: 좌식 | O29: 3.0T | P29: 클라크 | Q29: EPX30 | R29: EPX360-7069-9652KF | S29: 41640 | T29: 0 | V29: N | Z29: 케이앤엘 | AA29: 43282 | AB29: 43282 | AC29: 700000 | AD29: 32920000
A30: 27 | B30: =MID(F30,8,3) -> 027 | C30: =MID(F30,1,1) -> T | D30: =MID(F30,3,1) -> B | E30: =MID(F30,2,1) -> F | F30: TFB15-0027 | G30: 대신 마산공장 | H30: 대신 마산공장 | I30: 임대 | J30: 이승희 | K30: 2공장-앨리슨 | L30: 대신-마산-27 | M30: 주간 | N30: 입식 | O30: 1.5T | P30: 도요다 | R30: 7FBR15-54621 V3 | S30: 41275 | T30: 0 | V30: N | Z30: 케이앤엘 | AA30: 43282 | AB30: 43282 | AC30: 350000 | AD30: 6900000
A31: 28 | B31: =MID(F31,8,3) -> 028 | C31: =MID(F31,1,1) -> C | D31: =MID(F31,3,1) -> B | E31: =MID(F31,2,1) -> F | F31: CFB18-0028 | G31: 대동기어 | H31: 엘소 | I31: 임대 | J31: 김한경 | K31: 2공장 | L31: 대동기어-28 | M31: 주간 | N31: 입식 | O31: 1.8T | P31: 클라크 | Q31: CRX18 | R31: CRX148-3262-9658KF | S31: 42005 | T31: 0 | V31: Y | W31: KB | X31: 케이앤엘 | Y31: 대동기어 | Z31: 케이앤엘 | AA31: 43282 | AB31: 45748 | AC31: 442000 | AD31: 4121000
A32: 29 | B32: =MID(F32,8,3) -> 029 | C32: =MID(F32,1,1) -> T | D32: =MID(F32,3,1) -> B | E32: =MID(F32,2,1) -> F | F32: TFB10-0029 | G32: 대신 마산공장 | H32: 대신 마산공장 | I32: 임대 | J32: 이승희 | K32: 1공장-2층 | L32: 대신-마산-29 | M32: 주간 | N32: 입식 | O32: 1.0T | P32: 도요다 | R32: 7F3RK10 | S32: 38353 | T32: 0 | V32: N | Z32: 케이앤엘 | AA32: 43556 | AB32: 43556 | AC32: 350000 | AD32: 3500000
A33: 30 | B33: =MID(F33,8,3) -> 030 | C33: =MID(F33,1,1) -> T | D33: =MID(F33,3,1) -> B | E33: =MID(F33,2,1) -> F | F33: TFB18-0030 | G33: 디에스아이 | H33: 디에스아이 | I33: 임대 | J33: 이승희 | K33: D반 | L33: 대신-DSI-30 | M33: 주간 | N33: 입식 | O33: 1.8T | P33: 도요다 | R33: 7FBR18-50359 V3 | S33: 40909 | T33: 0 | V33: N | Z33: 케이앤엘 | AA33: 43282 | AB33: 43282 | AC33: 350000 | AD33: 8400000
A34: 31 | B34: =MID(F34,8,3) -> 031 | C34: =MID(F34,1,1) -> T | D34: =MID(F34,3,1) -> B | E34: =MID(F34,2,1) -> F | F34: TFB10-0031 | G34: 디에스아이 | H34: 디에스아이 | I34: 임대 | J34: 이승희 | K34: S반(탬핑) | L34: 대신-DSI-31 | M34: 주간 | N34: 입식 | O34: 1.0T | P34: 도요다 | R34: 7FBRK10-10552 V3 | S34: 37622 | T34: 0 | V34: N | Z34: 케이앤엘 | AA34: 43282 | AB34: 43282 | AC34: 350000 | AD34: 3221000
A35: 32 | B35: =MID(F35,8,3) -> 032 | C35: =MID(F35,1,1) -> T | D35: =MID(F35,3,1) -> B | E35: =MID(F35,2,1) -> F | F35: TFB25-0032 | G35: 디에스아이 | H35: 디에스아이 | I35: 임대 | J35: 이승희 | K35: 1층 | L35: 대신-DSI-32 | M35: 주간 | N35: 좌식 | O35: 2.5T | P35: 도요다 | R35: 7FB25-49399 V3 | S35: 40909 | T35: 0 | V35: N | Z35: 케이앤엘 | AA35: 43282 | AB35: 43282 | AC35: 500000 | AD35: 17700000
A36: 33 | B36: =MID(F36,8,3) -> 033 | C36: =MID(F36,1,1) -> T | D36: =MID(F36,3,1) -> B | E36: =MID(F36,2,1) -> F | F36: TFB15-0033 | G36: 디에스아이 | H36: 디에스아이 | I36: 임대 | J36: 이승희 | K36: 1층 | L36: 대신-DSI-33 | M36: 주간 | N36: 입식 | O36: 1.5T | P36: 도요다 | R36: 7FBRK10-50142 V3 | S36: 41275 | T36: 0 | V36: N | Z36: 케이앤엘 | AA36: 43282 | AB36: 43282 | AC36: 350000 | AD36: 4321000
A37: 34 | B37: =MID(F37,8,3) -> 034 | C37: =MID(F37,1,1) -> E | D37: =MID(F37,3,1) -> B | E37: =MID(F37,2,1) -> F | F37: EFB18-0034 | G37: 디에스아이 | H37: 디에스아이 | I37: 임대 | J37: 이승희 | K37: 1층 | L37: 대신-DSI-34 | M37: 주간 | N37: 입식 | O37: 1.8T | P37: TCM | R37: FR18-7-82P01858 V3 | S37: 39448 | T37: 0 | V37: N | Z37: 케이앤엘 | AA37: 43282 | AB37: 43282 | AC37: 350000 | AD37: 5957000
A38: 35 | B38: =MID(F38,8,3) -> 035 | C38: =MID(F38,1,1) -> T | D38: =MID(F38,3,1) -> B | E38: =MID(F38,2,1) -> F | F38: TFB15-0035 | G38: 디에스아이 | H38: 디에스아이 | I38: 임대 | J38: 이승희 | K38: 2층 | L38: 대신-DSI-35 | M38: 주간 | N38: 입식 | O38: 1.5T | P38: 도요다 | R38: 7FBR15-14430 V3 | S38: 37622 | T38: 0 | V38: N | Z38: 케이앤엘 | AA38: 43282 | AB38: 43282 | AC38: 350000 | AD38: 3500000
A39: 36 | B39: =MID(F39,8,3) -> 036 | C39: =MID(F39,1,1) -> T | D39: =MID(F39,3,1) -> B | E39: =MID(F39,2,1) -> F | F39: TFB25-0036 | G39: (주)알맥 | H39: (주)알맥 | I39: 임대 | J39: 이승희 | K39: 압출5호 | L39: 경남금속-36 | M39: 주간 | N39: 좌식 | O39: 2.5T | P39: 도요다 | Q39: 7FB25 | R39: 7FB25-49347 V3 | S39: 40909 | T39: 0 | V39: N | Z39: 케이앤엘 | AA39: 43282 | AB39: 43282 | AC39: 484000 | AD39: 21020000
A40: 37 | B40: =MID(F40,8,3) -> 037 | C40: =MID(F40,1,1) -> T | D40: =MID(F40,3,1) -> B | E40: =MID(F40,2,1) -> F | F40: TFB25-0037 | G40: (주)알맥 | H40: (주)알맥 | I40: 임대 | J40: 이승희 | K40: 압출2,3호 | L40: 경남금속-37 | M40: 주간 | N40: 좌식 | O40: 2.5T | P40: 도요다 | Q40: 7FB25 | R40: 7FB25-49525 V3 | S40: 41275 | T40: 0 | V40: N | Z40: 케이앤엘 | AA40: 43282 | AB40: 43282 | AC40: 489000 | AD40: 18700000
A41: 38 | B41: =MID(F41,8,3) -> 038 | C41: =MID(F41,1,1) -> T | D41: =MID(F41,3,1) -> B | E41: =MID(F41,2,1) -> F | F41: TFB15-0038 | G41: (주)알맥 | H41: (주)알맥 | I41: 임대 | J41: 이승희 | K41: 수정반 | L41: 경남금속-38 | M41: 주간 | N41: 좌식 | O41: 1.5T | P41: 도요다 | Q41: 7FBL15 | R41: 7FBL15-21543 V3 | S41: 40544 | T41: 0 | V41: N | Z41: 케이앤엘 | AA41: 43282 | AB41: 43282 | AC41: 360000 | AD41: 12870000
...

Sheet 예비 및 여유차량
A1: 예비차량 현황 _ 2025. 11월 20일 현재
A3: 1. 예비차량 List
B4: 동력 | C4: 장비 No | D4: 사업장 | E4: 상태 | F4: 담당자 | G4: 배치장소 | H4: 배치No | I4: 규격 | J4: 톤수 | K4: 제작처 | L4: 모델명 | M4: 차대번호 | N4: 년식 | O4: 보험 | P4: 자산처 | Q4: 자산등록일 | R4: 임대시작일 (철수일자) | S4: 임대료 | T4: 차량가액 | U4: 잔존가 | V4: 비 고
A5: 전동 | B5: =MID(C5,3,1) -> B | C5: CFB18-0006 | D5: 케이엔엘 | E5: 예비 | F5: 이승희 | G5: 지게차 창고 | H5: 예비-06 | I5: 좌식 | J5: 1.8T | K5: 클라크 | L5: EPX18 | M5: EPX162-0965-9818KF | N5: 40909 | O5: N | P5: 케이엔엘 | Q5: 43831 | R5: 45383 | S5: 0 | T5: 18000000 | U5: -10650084
A6: 전동 | B6: =MID(C6,3,1) -> B | C6: CFB18-0019 | D6: 케이엔엘 | E6: 예비 | F6: 이승희 | G6: 지게차 창고 | H6: 예비-19 | I6: 좌식 | J6: 1.8T | K6: 클라크 | L6: EPX18 | M6: EPX162-0967-9818KF | N6: 40909 | O6: N | P6: 케이엔엘 | Q6: 44013 | R6: 45413 | S6: 0 | T6: 8500000
A7: 전동 | B7: =MID(C7,3,1) -> B | C7: TFB15-0051 | D7: 케이엔엘 | E7: 예비 | F7: 이승희 | G7: 지게차 창고 | H7: 예비-51 | I7: 좌식 | J7: 1.5T | K7: 도요다 | L7: 7FBL15 | M7: 7FBL15-13468 V3 FM | N7: 37622 | O7: N | P7: 케이엔엘 | Q7: 43617 | R7: 45778 | S7: 0 | T7: 10830000 | U7: -12978040 | V7: →덴소 마산공장 투입 검토중
A8: 디젤 | B8: =MID(C8,3,1) -> O | C8: CFO35-0075 | D8: 케이엔엘 | E8: 예비 | F8: 이승희 | G8: 지게차 창고 | H8: 예비-75 | I8: 좌식 | J8: 3.5T | K8: 클라크 | L8: FX353D-2 | M8: CMP450D-1691-9588KF | N8: 39448 | O8: N | P8: 케이엔엘 | Q8: 43344 | R8: 45444 | S8: 0 | T8: 9830710 | U8: -37748788 | V8: * 3단마스트, 에어컨 미 장착, 튜부타이어
A9: 디젤 | B9: =MID(C9,3,1) -> O | C9: CFO35-0078 | D9: 케이엔엘 | E9: 예비 | F9: 이승희 | G9: 지게차 창고 | H9: 예비-78 | I9: 좌식 | J9: 3.5T | K9: 클라크 | L9: C35KD | M9: P455D-0050-9783KF | N9: 40544 | O9: Y | P9: 케이엔엘 | Q9: 43344 | R9: 45839 | S9: 0 | T9: 11000000 | U9: -49492863 | V9: * 3단마스트, 에어컨 미 장착, 튜부타이어
A10: 디젤 | B10: =MID(C10,3,1) -> O | C10: DFO40-0134 | D10: 케이엔엘 | E10: 예비 | F10: 이승희 | G10: 지게차 창고 | H10: 예비-134 | I10: 좌식 | J10: 4.0T | K10: 두산 | L10: D40S-5 | M10: FDB02-1240-01157 | N10: 40817 | O10: Y | P10: 엘소 | Q10: 40857 | R10: 45870 | S10: 0 | T10: 38850000 | U10: -48763261 | V10: * 2단 표준마스트, 에어컨 미 장착, 튜부타이어
A11: 전동 | B11: =MID(C11,3,1) -> B | C11: STB20-0149 | D11: 케이엔엘 | E11: 예비 | F11: 이승희 | G11: 지게차 창고 | H11: 예비-149 | I11: 견인 | J11: 2.0T | K11: 수성산업 | L11: SCT2000N | M11: SCT200N-CTBHB0002 | N11: 42856 | O11: N | P11: 엘소 | Q11: 42856 | R11: 45597 | S11: 0 | T11: 8000000 | U11: -18111500
A12: 전동 | B12: =MID(C12,3,1) -> B | C12: EFB15-0126 | D12: 케이엔엘 | E12: 예비 | F12: 이승희 | G12: 지게차 창고 | H12: 예비-126 | I12: 핸드리프트 | J12: 1.5T | K12: 게이트 | L12: GR15 | M12: GR15-1805016 | N12: 43221 | O12: N | P12: 케이엔엘 | Q12: 43221 | R12: 45444 | S12: 0 | T12: 13000000 | U12: -22321480
A13: 디젤 | B13: =MID(C13,3,1) -> O | C13: DFO30-0168 | D13: 케이엔엘 | E13: 예비 | F13: 이승희 | G13: 지게차 창고 | H13: 예비-168 | I13: 좌식 | J13: 3.0T | K13: 두산 | L13: D30S-5 | M13: FDA06-1000-12094 | N13: 40941 | O13: N | P13: 케이엔엘 | Q13: 44875 | R13: 45870 | S13: 0 | T13: 2000000 | U13: -21247670
A14: 디젤 | B14: =MID(C14,3,1) -> O | C14: DFO30-0213 | D14: 케이엔엘 | E14: 예비 | F14: 이승희 | G14: 지게차 창고 | H14: 예비-213 | I14: 좌식 | J14: 3.0T | K14: 두산 | L14: D30SE-9 | M14: FDA2H-5122-01601 | N14: 44986 | O14: Y | P14: 엘소 | Q14: 44998 | R14: 45870 | S14: 0 | T14: 38520000 | U14: 18819687
A15: 전동 | B15: =MID(C15,3,1) -> B | C15: SHB20-0272 | D15: 케이엔엘 | E15: 예비 | F15: 이승희 | G15: 지게차 창고 | H15: 예비-272 | I15: 핸드파레트 | J15: 2.0T | K15: 수성산업 | L15: SWP-2000(특) | M15: WPCDH0031 | N15: 45170 | O15: N | P15: 케이엔엘 | Q15: 45200 | R15: 45839 | S15: 0 | T15: 8400000 | U15: 2700000
A16: 전동 | B16: =MID(C16,3,1) -> B | C16: CFB30-0328 | D16: 케이엔엘 | E16: 예비 | F16: 이승희 | G16: 지게차 창고 | H16: 예비-328 | I16: 좌식 | J16: 3.0T | K16: 클라크 | L16: EPX30FL | M16: EPX360FL 3108 9959KF | N16: 43770 | O16: N | P16: 케이엔엘 | Q16: 45510 | R16: 45849 | S16: 0 | T16: 16000000 | U16: 13001130
A17: 디젤 | B17: =MID(C17,3,1) -> O | C17: CFO45-0172 | D17: 케이엔엘 | E17: 예비 | F17: 이승희 | G17: 지게차 창고 | H17: 예비-172 | I17: 좌식 | J17: 4.5T | K17: 클라크 | L17: C45KD | M17: P455D00419783KF | N17: 40544 | O17: N | P17: 케이엔엘 | Q17: 44927 | R17: 45383 | S17: 0 | T17: 5000000 | U17: -3717353 | V17: → 알맥 사천 공장 투입검토
A18: 전동 | B18: =MID(C18,3,1) -> B | C18: CFB25-0100 | D18: 케이엔엘 | E18: 예비 | F18: 이승희 | G18: 지게차 창고 | H18: 예비-100 | I18: 좌식 | J18: 2.5T | K18: 클라크 | L18: EPX25 | M18: EPX360-6510-9652 | N18: 44075 | O18: N | P18: 케이엔엘 | Q18: 44652 | R18: 45901 | S18: 0 | T18: 16000000 | U18: -6659896
A19: 전동 | B19: =MID(C19,3,1) -> B | C19: LHB15-0331 | D19: 케이엔엘 | E19: 예비 | F19: 이승희 | G19: 지게차 창고 | H19: 예비-331 | I19: 핸드리프트 | J19: 1.5T | K19: 티엠씨 엘앤에프 | L19: TR15R | M19: TR15R-2408207 | N19: 45516 | O19: N | P19: 케이엔엘 | Q19: 45520 | R19: 45729 | S19: 0 | T19: 15000000 | U19: 12517742
A20: 디젤 | B20: =MID(C20,3,1) -> O | C20: CFO45-0175 | D20: 케이엔엘 | E20: 예비 | F20: 이승희 | G20: 볼보 | H20: 예비-175 | I20: 좌식 | J20: 4.5T | K20: 클라크 | L20: C45KD | M20: P455D01379885KF | N20: 41426 | O20: Y | P20: 케이엔엘 | Q20: 44927 | R20: 45839 | S20: 0 | T20: 5000000 | U20: 8745460 | V20: →볼보(코스) 철수대상차량
A21: 디젤 | B21: =MID(C21,3,1) -> O | C21: CFO45-0176 | D21: 케이엔엘 | E21: 예비 | F21: 이승희 | G21: 볼보 | H21: 예비-176 | I21: 좌식 | J21: 4.5T | K21: 클라크 | L21: C45KD | M21: P455D01659885KF | N21: 41548 | O21: N | P21: 케이엔엘 | Q21: 44927 | R21: 45839 | S21: 0 | T21: 5000000 | U21: 6862910 | V21: →볼보(코스) 철수대상차량
A22: 핸드 | B22: =MID(C22,3,1) -> B | C22: ETB15-0206 | D22: 케이엔엘 | E22: 예비 | F22: 이승희 | G22: 볼보 | H22: 예비-206 | I22: 견인 | J22: 1.5T | K22: 동명 | L22: HT15X | M22: HT15X-0425 | N22: 38443 | O22: N | P22: 케이엔엘 | Q22: 44927 | R22: 45839 | S22: 0 | T22: 3000000 | U22: 3075000 | V22: →볼보(코스) 철수대상차량
A23: 견인 | B23: =MID(C23,3,1) -> B | C23: CTB70-0418 | D23: 케이엔엘 | E23: 예비 | F23: 이승희 | G23: 볼보 | H23: 예비-418 | I23: 견인 | J23: 7.0T | K23: 클라크 | L23: CTX470 | M23: CTX470-0142-9812KF | N23: 40948 | O23: N | P23: 케이엔엘 | Q23: 45839 | R23: 45839 | S23: 0 | T23: 1000000 | U23: 1010820 | V23: →볼보(코스) 철수대상차량
A24: 견인 | B24: =MID(C24,3,1) -> B | C24: CTB70-0421 | D24: 케이엔엘 | E24: 예비 | F24: 이승희 | G24: 볼보 | H24: 예비-421 | I24: 견인 | J24: 7.0T | K24: 클라크 | L24: CTX470 | M24: CTX470-0168-9812KF | N24: 40997 | O24: N | P24: 케이엔엘 | Q24: 45839 | R24: 45839 | S24: 0 | T24: 1000000 | U24: 1000000 | V24: →볼보(코스) 철수대상차량
A26: 2. 대체 투입용 차량
A27: 디젤 | B27: =MID(C27,3,1) -> O | C27: DFO25-0106 | D27: 케이엔엘 | E27: 예비 | F27: 이승희 | G27: 지게차 창고 | H27: 예비-106 | I27: 좌식 | J27: 2.5T | K27: 두산 | L27: D25S-3 | M27: D25S3-1495 | N27: 37257 | O27: N | P27: 케이엔엘 | Q27: 43831 | R27: 45444 | S27: 0 | T27: 5000000 | U27: 9437000 | V27: → 2.5톤 엔진 단기 대체차량 활용
A28: 디젤 | B28: =MID(C28,3,1) -> O | C28: DFO70-0081 | D28: 케이엔엘 | E28: 예비 | F28: 이승희 | G28: 지게차 창고 | H28: 예비-81 | I28: 좌식 | J28: 7.0T | K28: 두산 | L28: D70EV-7PLUS | M28: FDB0V-2610-03745 | N28: 43800 | O28: N | P28: 케이엔엘 | Q28: 43800 | R28: 45444 | S28: 0 | T28: 61450000 | U28: 10090620 | V28: → 세아항공방산소재 대체운용 차량
A29: 전동 | B29: =MID(C29,3,1) -> B | C29: DFB18-0120 | D29: 케이엔엘 | E29: 예비 | F29: 이승희 | G29: 지게차 창고 | H29: 예비-120 | I29: 좌식 | J29: 1.8T | K29: 두산 | L29: B18S-5 | M29: FBAOC-1380-00262 | N29: 40817 | O29: Y | P29: 엘소 | Q29: 40817 | R29: 45444 | S29: 0 | T29: 23650000 | U29: -25340460 | V29: → 1.8T~2T 장비 대체운용 차량
A30: 전동 | B30: =MID(C30,3,1) -> B | C30: CFB30-0321 | D30: 케이엔엘 | E30: 예비 | F30: 이승희 | G30: 엘소창원공장 | H30: 예비-321 | I30: 좌식 | J30: 3.0T | K30: 클라크 | L30: EPG30 | M30: EPG358-0129-9579KF | N30: 38018 | O30: N | P30: 케이엔엘 | Q30: 45474 | R30: 45749 | S30: 0 | T30: 3300000 | U30: 9352750 | V30: → 2.5T~3.0T 사이 장비 대체운용 차량
A32: 3. 사업장 예비차량
C33: 장비 No | D33: 사업장 | E33: 상태 | F33: 담당자 | G33: 배치장소 | H33: 배치No | I33: 규격 | J33: 톤수 | K33: 제작처 | L33: 모델명 | M33: 차대번호 | N33: 년식 | O33: 보험 | P33: 자산처 | Q33: 자산등록일 | R33: 임대시작일 | S33: 임대료 | T33: 차량가액 | U33: 잔존가 | V33: 비 고
A34: 디젤 | B34: =MID(C34,3,1) -> O | C34: DFO30-0154 | D34: 셰플러 | E34: 임대 | F34: 이상용 | G34: 셰플러 | H34: 예비-154 | I34: 좌식 | J34: 3.0T | K34: 두산 | L34: D30S-5 | M34: FDA06-1000-11572 | N34: 40817 | O34: Y | P34: 엘소 | Q34: 40817 | R34: 44867 | S34: 396000 | T34: 29510000 | U34: 29665244
A35: 전동 | B35: =MID(C35,3,1) -> B | C35: CFB25-0189 | D35: 디와이파워 | E35: 임대 | F35: 이승희 | G35: 디와이파워 | H35: 예비 | I35: 입식 | J35: 2.5T | K35: 클라크 | L35: CRX25 | M35: CRX205-2290-9659-KF | N35: 41671 | O35: N | P35: 케이엔엘 | Q35: 44927 | R35: 45132 | S35: 0 | T35: 3000000 | U35: 5550360
A36: 디젤 | B36: =MID(C36,3,1) -> O | C36: DFOA6-0059 | D36: 케이엔엘 | E36: 예비 | F36: 이승희 | G36: 녹산공장-예비 | H36: 예비-59 | I36: 좌식 | J36: 16T | K36: 두산 | L36: D160S-7 | M36: FDC0B-2290-00085 | N36: 42528 | O36: N | P36: 청운로지스 | Q36: 43831 | R36: 45962 | S36: 0 | T36: 72975000
A37: 전동 | B37: =MID(C37,3,1) -> B | C37: CFB50-0183 | D37: 볼보 | E37: 임대 | F37: 최수진 | G37: 예비 | H37: 가공-183 | I37: 좌식 | J37: 5.0T | K37: 클라크 | L37: GEX50 | M37: GEX450-0377-9868-KF | N37: 43191 | O37: N | P37: 케이엔엘 | Q37: 44927 | R37: 44927 | S37: 1150000 | T37: 8085000
A38: 디젤 | B38: =MID(C38,3,1) -> B | C38: CFB25-0199 | D38: 볼보 | E38: 임대 | F38: 최수진 | G38: 예비 | H38: 가공-199 | I38: 입식 | J38: 2.5T | K38: 클라크 | L38: CRX25FL | M38: CRX205-2879-9957-KF | N38: 44197 | O38: N | P38: 케이엔엘 | Q38: 44927 | R38: 44927 | S38: 800000 | T38: 20604000
A39: 전동 | B39: =MID(C39,3,1) -> B | C39: CFB25-0202 | D39: 볼보 | E39: 임대 | F39: 최수진 | G39: 예비 | H39: 가공-202 | I39: 입식 | J39: 2.5T | K39: 클라크 | L39: CRX25FL | M39: CRX205-3905-9957-KF | N39: 44835 | O39: N | P39: 케이엔엘 | Q39: 44927 | R39: 44927 | S39: 800000 | T39: 30873000
A40: 전동 | B40: =MID(C40,3,1) -> B | C40: ETB15-0204 | D40: 볼보 | E40: 임대 | F40: 최수진 | G40: 예비 | H40: 가공-204 | I40: 운반 | J40: 1.5T | K40: T.M.C | L40: TPT15X | M40: TPT15X2030457 | N40: 40969 | O40: N | P40: 케이엔엘 | Q40: 44927 | R40: 44927 | S40: 500000 | T40: 3000000
A41: 디젤 | B41: =MID(C41,3,1) -> O | C41: CFO50-0367 | D41: 볼보 | E41: 임대 | F41: 최수진 | G41: 예비 | H41: 조립-367 | I41: 좌식 | J41: 5.0T | K41: 클라크 | L41: C50KD | M41: P455D 01909964KF | N41: 43207 | O41: N | P41: 케이엔엘 | Q41: 45839 | R41: 45839 | S41: 1150000 | T41: 5000000
A42: 디젤 | B42: =MID(C42,3,1) -> O | C42: CFO45-0372 | D42: 볼보 | E42: 임대 | F42: 최수진 | G42: 예비 | H42: 조립-372 | I42: 좌식 | J42: 4.5T | K42: 클라크 | L42: C45KD | M42: P455D 02739964KF | N42: 43641 | O42: N | P42: 케이엔엘 | Q42: 45839 | R42: 45839 | S42: 1000000 | T42: 5000000
A43: 디젤 | B43: =MID(C43,3,1) -> O | C43: CFO45-0376 | D43: 볼보 | E43: 임대 | F43: 최수진 | G43: 예비 | H43: 조립-376 | I43: 좌식 | J43: 4.5T | K43: 클라크 | L43: C45KD | M43: P455D 01529964KF | N43: 42935 | O43: N | P43: 케이엔엘 | Q43: 45839 | R43: 45839 | S43: 1000000 | T43: 5000000
...

Sheet 예비차량 Summary
B2: KNL 예비 차량 현황
B4: 구분 | C4: 총 보유대수 | E4: 예비차량 | F4: 대체차량 | G4: 사업장 예비차량 | H4: 폐기/매각 차량
B5: 장비대수 | C5: =SUM(C21:Z21) -> 42 | E5: =SUM(C10:H20) -> 20 | F5: =SUM(I10:N20) -> 4 | G5: =SUM(O10:T20) -> 11 | H5: =SUM(U10:Z20) -> 7
B7: Ton | C7: 예비차량 | I7: 대체 투입용 차량 | O7: 사업장 예비차량 | U7: 폐기/매각 대기차량
C8: 디젤 | D8: 전동 | I8: 디젤 | J8: 전동 | O8: 디젤 | P8: 전동 | U8: 디젤 | V8: 전동
C9: 좌식 | D9: 좌식 | E9: 입식 | F9: 핸드파레트 | G9: 핸드리프트 | H9: 기타 | I9: 좌식 | J9: 좌식 | K9: 입식 | L9: 핸드파레트 | M9: 핸드리프트 | N9: 기타 | O9: 좌식 | P9: 좌식 | Q9: 입식 | R9: 핸드파레트 | S9: 핸드리프트 | T9: 기타 | U9: 좌식 | V9: 좌식 | W9: 입식 | X9: 핸드파레트 | Y9: 핸드리프트 | Z9: 기타
B10: 1.5T | C10: =COUNTIFS('예비 및 여유차량'!$B$5:$B$24,"O",'예비 및 여유차량'!$I$5:$I$24,"좌식",'예비 및 여유차량'!$J$5:$J$24,"1.5T") -> 0 | D10: =COUNTIFS('예비 및 여유차량'!$B$5:$B$24,"B",'예비 및 여유차량'!$I$5:$I$24,"좌식",'예비 및 여유차량'!$J$5:$J$24,"1.5T") -> 1 | E10: =COUNTIFS('예비 및 여유차량'!$B$5:$B$24,"B",'예비 및 여유차량'!$I$5:$I$24,"입식",'예비 및 여유차량'!$J$5:$J$24,"1.5T") -> 0 | F10: =COUNTIFS('예비 및 여유차량'!$B$5:$B$24,"B",'예비 및 여유차량'!$I$5:$I$24,"핸드파레트",'예비 및 여유차량'!$J$5:$J$24,"1.5T") -> 0 | G10: =COUNTIFS('예비 및 여유차량'!$B$5:$B$24,"B",'예비 및 여유차량'!$I$5:$I$24,"핸드리프트",'예비 및 여유차량'!$J$5:$J$24,"1.5T") -> 2 | H10: =COUNTIFS('예비 및 여유차량'!$B$5:$B$24,"B",'예비 및 여유차량'!$I$5:$I$24,"<>핸드리프트",'예비 및 여유차량'!$I$5:$I$24,"<>핸드파레트",'예비 및 여유차량'!$I$5:$I$24,"<>입식",'예비 및 여유차량'!$I$5:$I$24,"<>좌식",'예비 및 여유차량'!$J$5:$J$24,"1.5T") -> 1 | I10: =COUNTIFS('예비 및 여유차량'!B27:B30,"O",'예비 및 여유차량'!$I$27:$I$30,"좌식",'예비 및 여유차량'!$J$27:$J$30,"1.5T") -> 0 | J10: =COUNTIFS('예비 및 여유차량'!B27:B30,"B",'예비 및 여유차량'!$I$27:$I$30,"좌식",'예비 및 여유차량'!$J$27:$J$30,"1.5T") -> 0 | K10: =COUNTIFS('예비 및 여유차량'!B27:B30,"B",'예비 및 여유차량'!$I$27:$I$30,"입식",'예비 및 여유차량'!$J$27:$J$30,"1.5T") -> 0 | L10: =COUNTIFS('예비 및 여유차량'!B27:B30,"B",'예비 및 여유차량'!$I$27:$I$30,"핸드파레트",'예비 및 여유차량'!$J$27:$J$30,"1.5T") -> 0 | M10: =COUNTIFS('예비 및 여유차량'!A27:A30,"B",'예비 및 여유차량'!$I$27:$I$30,"핸드리프트",'예비 및 여유차량'!$J$27:$J$30,"1.5T") -> 0 | N10: =COUNTIFS('예비 및 여유차량'!A27:A30,"B",'예비 및 여유차량'!I27:I30,"<>핸드리프트",'예비 및 여유차량'!I27:I30,"<>핸드파레트",'예비 및 여유차량'!I27:I30,"<>입식",'예비 및 여유차량'!I27:I30,"<>좌식",'예비 및 여유차량'!J27:J30,"1.5T") -> 0 | O10: =COUNTIFS('예비 및 여유차량'!$B$34:$B$44,"O",'예비 및 여유차량'!$I$34:$I$44,"좌식",'예비 및 여유차량'!$J$34:$J$44,"1.5T") -> 0 | P10: =COUNTIFS('예비 및 여유차량'!$B$34:$B$44,"B",'예비 및 여유차량'!$I$34:$I$44,"좌식",'예비 및 여유차량'!$J$34:$J$44,"1.5T") -> 0 | Q10: =COUNTIFS('예비 및 여유차량'!$B$34:$B$44,"B",'예비 및 여유차량'!$I$34:$I$44,"입식",'예비 및 여유차량'!$J$34:$J$44,"1.5T") -> 0 | R10: =COUNTIFS('예비 및 여유차량'!$B$34:$B$44,"B",'예비 및 여유차량'!$I$34:$I$44,"핸드파레트",'예비 및 여유차량'!$J$34:$J$44,"1.5T") -> 0 | S10: =COUNTIFS('예비 및 여유차량'!$B$34:$B$44,"B",'예비 및 여유차량'!$I$34:$I$44,"핸드리프트",'예비 및 여유차량'!$J$34:$J$44,"1.5T") -> 0 | T10: =COUNTIFS('예비 및 여유차량'!$B$34:$B$44,"B",'예비 및 여유차량'!$I$34:$I$44,"<>핸드리프트",'예비 및 여유차량'!$I$34:$I$44,"<>핸드파레트",'예비 및 여유차량'!$I$34:$I$44,"<>입식",'예비 및 여유차량'!$I$34:$I$44,"<>좌식",'예비 및 여유차량'!$J$34:$J$44,"1.5T") -> 1 | U10: =COUNTIFS('예비 및 여유차량'!$B$55:$B$61,"O",'예비 및 여유차량'!$I$55:$I$61,"좌식",'예비 및 여유차량'!$J$55:$J$61,"1.5T") -> 0 | V10: =COUNTIFS('예비 및 여유차량'!$B$55:$B$61,"B",'예비 및 여유차량'!$I$55:$I$61,"좌식",'예비 및 여유차량'!$J$55:$J$61,"1.5T") -> 0 | W10: =COUNTIFS('예비 및 여유차량'!$B$55:$B$61,"B",'예비 및 여유차량'!$I$55:$I$61,"입식",'예비 및 여유차량'!$J$55:$J$61,"1.5T") -> 0 | X10: =COUNTIFS('예비 및 여유차량'!$B$55:$B$61,"B",'예비 및 여유차량'!$I$55:$I$61,"핸드파레트",'예비 및 여유차량'!$J$55:$J$61,"1.5T") -> 0 | Y10: =COUNTIFS('예비 및 여유차량'!$B$55:$B$61,"B",'예비 및 여유차량'!$I$55:$I$61,"핸드리프트",'예비 및 여유차량'!$J$55:$J$61,"1.5T") -> 0 | Z10: =COUNTIFS('예비 및 여유차량'!$B$55:$B$61,"B",'예비 및 여유차량'!$I$55:$I$61,"<>핸드리프트",'예비 및 여유차량'!$I$55:$I$61,"<>핸드파레트",'예비 및 여유차량'!$I$55:$I$61,"<>입식",'예비 및 여유차량'!$I$55:$I$61,"<>좌식",'예비 및 여유차량'!$J$55:$J$61,"1.5T") -> 0
B11: 1.8T | C11: =COUNTIFS('예비 및 여유차량'!$B$5:$B$24,"O",'예비 및 여유차량'!$I$5:$I$24,"좌식",'예비 및 여유차량'!$J$5:$J$24,"1.8T") -> 0 | D11: =COUNTIFS('예비 및 여유차량'!$B$5:$B$24,"B",'예비 및 여유차량'!$I$5:$I$24,"좌식",'예비 및 여유차량'!$J$5:$J$24,"1.8T") -> 2 | E11: =COUNTIFS('예비 및 여유차량'!$B$5:$B$24,"B",'예비 및 여유차량'!$I$5:$I$24,"입식",'예비 및 여유차량'!$J$5:$J$24,"1.8T") -> 0 | F11: =COUNTIFS('예비 및 여유차량'!$B$5:$B$24,"B",'예비 및 여유차량'!$I$5:$I$24,"핸드파레트",'예비 및 여유차량'!$J$5:$J$24,"1.8T") -> 0 | G11: =COUNTIFS('예비 및 여유차량'!$B$5:$B$24,"B",'예비 및 여유차량'!$I$5:$I$24,"핸드리프트",'예비 및 여유차량'!$J$5:$J$24,"1.8T") -> 0 | H11: =COUNTIFS('예비 및 여유차량'!$B$5:$B$24,"B",'예비 및 여유차량'!$I$5:$I$24,"<>핸드리프트",'예비 및 여유차량'!$I$5:$I$24,"<>핸드파레트",'예비 및 여유차량'!$I$5:$I$24,"<>입식",'예비 및 여유차량'!$I$5:$I$24,"<>좌식",'예비 및 여유차량'!$J$5:$J$24,"1.8T") -> 0 | I11: =COUNTIFS('예비 및 여유차량'!B27:B30,"O",'예비 및 여유차량'!$I$27:$I$30,"좌식",'예비 및 여유차량'!$J$27:$J$30,"1.8T") -> 0 | J11: =COUNTIFS('예비 및 여유차량'!B27:B30,"B",'예비 및 여유차량'!$I$27:$I$30,"좌식",'예비 및 여유차량'!$J$27:$J$30,"1.8T") -> 1 | K11: =COUNTIFS('예비 및 여유차량'!B27:B30,"B",'예비 및 여유차량'!$I$27:$I$30,"입식",'예비 및 여유차량'!$J$27:$J$30,"1.8T") -> 0 | L11: =COUNTIFS('예비 및 여유차량'!B27:B30,"B",'예비 및 여유차량'!$I$27:$I$30,"핸드파레트",'예비 및 여유차량'!$J$27:$J$30,"1.8T") -> 0 | M11: =COUNTIFS('예비 및 여유차량'!A27:A30,"B",'예비 및 여유차량'!$I$27:$I$30,"핸드리프트",'예비 및 여유차량'!$J$27:$J$30,"1.8T") -> 0 | N11: =COUNTIFS('예비 및 여유차량'!A28:A31,"B",'예비 및 여유차량'!I28:I31,"<>핸드리프트",'예비 및 여유차량'!I28:I31,"<>핸드파레트",'예비 및 여유차량'!I28:I31,"<>입식",'예비 및 여유차량'!I28:I31,"<>좌식",'예비 및 여유차량'!J28:J31,"1.8T") -> 0 | O11: =COUNTIFS('예비 및 여유차량'!$B$34:$B$44,"O",'예비 및 여유차량'!$I$34:$I$44,"좌식",'예비 및 여유차량'!$J$34:$J$44,"1.8T") -> 0 | P11: =COUNTIFS('예비 및 여유차량'!$B$34:$B$44,"B",'예비 및 여유차량'!$I$34:$I$44,"좌식",'예비 및 여유차량'!$J$34:$J$44,"1.8T") -> 0 | Q11: =COUNTIFS('예비 및 여유차량'!$B$34:$B$44,"B",'예비 및 여유차량'!$I$34:$I$44,"입식",'예비 및 여유차량'!$J$34:$J$44,"1.8T") -> 0 | R11: =COUNTIFS('예비 및 여유차량'!$B$34:$B$44,"B",'예비 및 여유차량'!$I$34:$I$44,"핸드파레트",'예비 및 여유차량'!$J$34:$J$44,"1.8T") -> 0 | S11: =COUNTIFS('예비 및 여유차량'!$B$34:$B$44,"B",'예비 및 여유차량'!$I$34:$I$44,"핸드리프트",'예비 및 여유차량'!$J$34:$J$44,"1.58T") -> 0 | T11: =COUNTIFS('예비 및 여유차량'!$B$34:$B$44,"B",'예비 및 여유차량'!$I$34:$I$44,"<>핸드리프트",'예비 및 여유차량'!$I$34:$I$44,"<>핸드파레트",'예비 및 여유차량'!$I$34:$I$44,"<>입식",'예비 및 여유차량'!$I$34:$I$44,"<>좌식",'예비 및 여유차량'!$J$34:$J$44,"1.8T") -> 0 | U11: =COUNTIFS('예비 및 여유차량'!$B$55:$B$61,"O",'예비 및 여유차량'!$I$55:$I$61,"좌식",'예비 및 여유차량'!$J$55:$J$61,"1.8T") -> 0 | V11: =COUNTIFS('예비 및 여유차량'!$B$55:$B$61,"B",'예비 및 여유차량'!$I$55:$I$61,"좌식",'예비 및 여유차량'!$J$55:$J$61,"1.8T") -> 0 | W11: =COUNTIFS('예비 및 여유차량'!$B$55:$B$61,"B",'예비 및 여유차량'!$I$55:$I$61,"입식",'예비 및 여유차량'!$J$55:$J$61,"1.8T") -> 0 | X11: =COUNTIFS('예비 및 여유차량'!$B$55:$B$61,"B",'예비 및 여유차량'!$I$55:$I$61,"핸드파레트",'예비 및 여유차량'!$J$55:$J$61,"1.8T") -> 0 | Y11: =COUNTIFS('예비 및 여유차량'!$B$55:$B$61,"B",'예비 및 여유차량'!$I$55:$I$61,"핸드리프트",'예비 및 여유차량'!$J$55:$J$61,"1.8T") -> 0 | Z11: =COUNTIFS('예비 및 여유차량'!$B$55:$B$61,"B",'예비 및 여유차량'!$I$55:$I$61,"<>핸드리프트",'예비 및 여유차량'!$I$55:$I$61,"<>핸드파레트",'예비 및 여유차량'!$I$55:$I$61,"<>입식",'예비 및 여유차량'!$I$55:$I$61,"<>좌식",'예비 및 여유차량'!$J$55:$J$61,"1.8T") -> 0
B12: 2.0T | C12: =COUNTIFS('예비 및 여유차량'!$B$5:$B$24,"O",'예비 및 여유차량'!$I$5:$I$24,"좌식",'예비 및 여유차량'!$J$5:$J$24,"2.0T") -> 0 | D12: =COUNTIFS('예비 및 여유차량'!$B$5:$B$24,"B",'예비 및 여유차량'!$I$5:$I$24,"좌식",'예비 및 여유차량'!$J$5:$J$24,"2.0T") -> 0 | E12: =COUNTIFS('예비 및 여유차량'!$B$5:$B$24,"B",'예비 및 여유차량'!$I$5:$I$24,"입식",'예비 및 여유차량'!$J$5:$J$24,"2.0T") -> 0 | F12: =COUNTIFS('예비 및 여유차량'!$B$5:$B$24,"B",'예비 및 여유차량'!$I$5:$I$24,"핸드파레트",'예비 및 여유차량'!$J$5:$J$24,"2.0T") -> 1 | G12: =COUNTIFS('예비 및 여유차량'!$B$5:$B$24,"B",'예비 및 여유차량'!$I$5:$I$24,"핸드리프트",'예비 및 여유차량'!$J$5:$J$24,"2.0T") -> 0 | H12: =COUNTIFS('예비 및 여유차량'!$B$5:$B$24,"B",'예비 및 여유차량'!$I$5:$I$24,"<>핸드리프트",'예비 및 여유차량'!$I$5:$I$24,"<>핸드파레트",'예비 및 여유차량'!$I$5:$I$24,"<>입식",'예비 및 여유차량'!$I$5:$I$24,"<>좌식",'예비 및 여유차량'!$J$5:$J$24,"2.0T") -> 1 | I12: =COUNTIFS('예비 및 여유차량'!B27:B30,"O",'예비 및 여유차량'!$I$27:$I$30,"좌식",'예비 및 여유차량'!$J$27:$J$30,"2.0T") -> 0 | J12: =COUNTIFS('예비 및 여유차량'!B27:B30,"B",'예비 및 여유차량'!$I$27:$I$30,"좌식",'예비 및 여유차량'!$J$27:$J$30,"2.0T") -> 0 | K12: =COUNTIFS('예비 및 여유차량'!B27:B30,"B",'예비 및 여유차량'!$I$27:$I$30,"입식",'예비 및 여유차량'!$J$27:$J$30,"2.0T") -> 0 | L12: =COUNTIFS('예비 및 여유차량'!B27:B30,"B",'예비 및 여유차량'!$I$27:$I$30,"핸드파레트",'예비 및 여유차량'!$J$27:$J$30,"2.0T") -> 0 | M12: =COUNTIFS('예비 및 여유차량'!A27:A30,"B",'예비 및 여유차량'!$I$27:$I$30,"핸드리프트",'예비 및 여유차량'!$J$27:$J$30,"2.0T") -> 0 | N12: =COUNTIFS('예비 및 여유차량'!A29:A32,"B",'예비 및 여유차량'!I29:I32,"<>핸드리프트",'예비 및 여유차량'!I29:I32,"<>핸드파레트",'예비 및 여유차량'!I29:I32,"<>입식",'예비 및 여유차량'!I29:I32,"<>좌식",'예비 및 여유차량'!J29:J32,"2.0T") -> 0 | O12: =COUNTIFS('예비 및 여유차량'!$B$34:$B$44,"O",'예비 및 여유차량'!$I$34:$I$44,"좌식",'예비 및 여유차량'!$J$34:$J$44,"2.0T") -> 0 | P12: =COUNTIFS('예비 및 여유차량'!$B$34:$B$44,"B",'예비 및 여유차량'!$I$34:$I$44,"좌식",'예비 및 여유차량'!$J$34:$J$44,"2.0T") -> 0 | Q12: =COUNTIFS('예비 및 여유차량'!$B$34:$B$44,"B",'예비 및 여유차량'!$I$34:$I$44,"입식",'예비 및 여유차량'!$J$34:$J$44,"2.0T") -> 0 | R12: =COUNTIFS('예비 및 여유차량'!$B$34:$B$44,"B",'예비 및 여유차량'!$I$34:$I$44,"핸드파레트",'예비 및 여유차량'!$J$34:$J$44,"2.0T") -> 0 | S12: =COUNTIFS('예비 및 여유차량'!$B$34:$B$44,"B",'예비 및 여유차량'!$I$34:$I$44,"핸드리프트",'예비 및 여유차량'!$J$34:$J$44,"2.0T") -> 0 | T12: =COUNTIFS('예비 및 여유차량'!$B$34:$B$44,"B",'예비 및 여유차량'!$I$34:$I$44,"<>핸드리프트",'예비 및 여유차량'!$I$34:$I$44,"<>핸드파레트",'예비 및 여유차량'!$I$34:$I$44,"<>입식",'예비 및 여유차량'!$I$34:$I$44,"<>좌식",'예비 및 여유차량'!$J$34:$J$44,"2.0T") -> 0 | U12: =COUNTIFS('예비 및 여유차량'!$B$55:$B$61,"O",'예비 및 여유차량'!$I$55:$I$61,"좌식",'예비 및 여유차량'!$J$55:$J$61,"2.0T") -> 0 | V12: =COUNTIFS('예비 및 여유차량'!$B$55:$B$61,"B",'예비 및 여유차량'!$I$55:$I$61,"좌식",'예비 및 여유차량'!$J$55:$J$61,"2.0T") -> 0 | W12: =COUNTIFS('예비 및 여유차량'!$B$55:$B$61,"B",'예비 및 여유차량'!$I$55:$I$61,"입식",'예비 및 여유차량'!$J$55:$J$61,"2.0T") -> 1 | X12: =COUNTIFS('예비 및 여유차량'!$B$55:$B$61,"B",'예비 및 여유차량'!$I$55:$I$61,"핸드파레트",'예비 및 여유차량'!$J$55:$J$61,"2.0T") -> 0 | Y12: =COUNTIFS('예비 및 여유차량'!$B$55:$B$61,"B",'예비 및 여유차량'!$I$55:$I$61,"핸ㄷ리프트",'예비 및 여유차량'!$J$55:$J$61,"2.0T") -> 0 | Z12: =COUNTIFS('예비 및 여유차량'!$B$55:$B$61,"B",'예비 및 여유차량'!$I$55:$I$61,"<>핸드리프트",'예비 및 여유차량'!$I$55:$I$61,"<>핸드파레트",'예비 및 여유차량'!$I$55:$I$61,"<>입식",'예비 및 여유차량'!$I$55:$I$61,"<>좌식",'예비 및 여유차량'!$J$55:$J$61,"2.0T") -> 0
B13: 2.5T | C13: =COUNTIFS('예비 및 여유차량'!$B$5:$B$24,"O",'예비 및 여유차량'!$I$5:$I$24,"좌식",'예비 및 여유차량'!$J$5:$J$24,"2.5T") -> 0 | D13: =COUNTIFS('예비 및 여유차량'!$B$5:$B$24,"B",'예비 및 여유차량'!$I$5:$I$24,"좌식",'예비 및 여유차량'!$J$5:$J$24,"2.5T") -> 1 | E13: =COUNTIFS('예비 및 여유차량'!$B$5:$B$24,"B",'예비 및 여유차량'!$I$5:$I$24,"입식",'예비 및 여유차량'!$J$5:$J$24,"2.5T") -> 0 | F13: =COUNTIFS('예비 및 여유차량'!$B$5:$B$24,"B",'예비 및 여유차량'!$I$5:$I$24,"핸드파레트",'예비 및 여유차량'!$J$5:$J$24,"2.5T") -> 0 | G13: =COUNTIFS('예비 및 여유차량'!$B$5:$B$24,"B",'예비 및 여유차량'!$I$5:$I$24,"핸드리프트",'예비 및 여유차량'!$J$5:$J$24,"2.5T") -> 0 | H13: =COUNTIFS('예비 및 여유차량'!$B$5:$B$24,"B",'예비 및 여유차량'!$I$5:$I$24,"<>핸드리프트",'예비 및 여유차량'!$I$5:$I$24,"<>핸드파레트",'예비 및 여유차량'!$I$5:$I$24,"<>입식",'예비 및 여유차량'!$I$5:$I$24,"<>좌식",'예비 및 여유차량'!$J$5:$J$24,"2.5T") -> 0 | I13: =COUNTIFS('예비 및 여유차량'!B27:B30,"O",'예비 및 여유차량'!$I$27:$I$30,"좌식",'예비 및 여유차량'!$J$27:$J$30,"2.5T") -> 1 | J13: =COUNTIFS('예비 및 여유차량'!B27:B30,"B",'예비 및 여유차량'!$I$27:$I$30,"좌식",'예비 및 여유차량'!$J$27:$J$30,"2.5T") -> 0 | K13: =COUNTIFS('예비 및 여유차량'!B27:B30,"B",'예비 및 여유차량'!$I$27:$I$30,"입식",'예비 및 여유차량'!$J$27:$J$30,"2.5T") -> 0 | L13: =COUNTIFS('예비 및 여유차량'!B27:B30,"B",'예비 및 여유차량'!$I$27:$I$30,"핸드파레트",'예비 및 여유차량'!$J$27:$J$30,"2.5T") -> 0 | M13: =COUNTIFS('예비 및 여유차량'!A27:A30,"B",'예비 및 여유차량'!$I$27:$I$30,"핸드리프트",'예비 및 여유차량'!$J$27:$J$30,"2.5T") -> 0 | N13: =COUNTIFS('예비 및 여유차량'!A30:A33,"B",'예비 및 여유차량'!I30:I33,"<>핸드리프트",'예비 및 여유차량'!I30:I33,"<>핸드파레트",'예비 및 여유차량'!I30:I33,"<>입식",'예비 및 여유차량'!I30:I33,"<>좌식",'예비 및 여유차량'!J30:J33,"2.5T") -> 0 | O13: =COUNTIFS('예비 및 여유차량'!$B$34:$B$44,"O",'예비 및 여유차량'!$I$34:$I$44,"좌식",'예비 및 여유차량'!$J$34:$J$44,"2.5T") -> 0 | P13: =COUNTIFS('예비 및 여유차량'!$B$34:$B$44,"B",'예비 및 여유차량'!$I$34:$I$44,"좌식",'예비 및 여유차량'!$J$34:$J$44,"2.5T") -> 0 | Q13: =COUNTIFS('예비 및 여유차량'!$B$34:$B$44,"B",'예비 및 여유차량'!$I$34:$I$44,"입식",'예비 및 여유차량'!$J$34:$J$44,"2.5T") -> 3 | R13: =COUNTIFS('예비 및 여유차량'!$B$34:$B$44,"B",'예비 및 여유차량'!$I$34:$I$44,"핸드파레트",'예비 및 여유차량'!$J$34:$J$44,"2.5T") -> 0 | S13: =COUNTIFS('예비 및 여유차량'!$B$34:$B$44,"B",'예비 및 여유차량'!$I$34:$I$44,"핸ㄷ리프트",'예비 및 여유차량'!$J$34:$J$44,"2.5T") -> 0 | T13: =COUNTIFS('예비 및 여유차량'!$B$34:$B$44,"B",'예비 및 여유차량'!$I$34:$I$44,"<>핸드리프트",'예비 및 여유차량'!$I$34:$I$44,"<>핸드파레트",'예비 및 여유차량'!$I$34:$I$44,"<>입식",'예비 및 여유차량'!$I$34:$I$44,"<>좌식",'예비 및 여유차량'!$J$34:$J$44,"2.5T") -> 0 | U13: =COUNTIFS('예비 및 여유차량'!$B$55:$B$61,"O",'예비 및 여유차량'!$I$55:$I$61,"좌식",'예비 및 여유차량'!$J$55:$J$61,"2.5T") -> 0 | V13: =COUNTIFS('예비 및 여유차량'!$B$55:$B$61,"B",'예비 및 여유차량'!$I$55:$I$61,"좌식",'예비 및 여유차량'!$J$55:$J$61,"2.5T") -> 2 | W13: =COUNTIFS('예비 및 여유차량'!$B$55:$B$61,"B",'예비 및 여유차량'!$I$55:$I$61,"입식",'예비 및 여유차량'!$J$55:$J$61,"2.5T") -> 4 | X13: =COUNTIFS('예비 및 여유차량'!$B$55:$B$61,"B",'예비 및 여유차량'!$I$55:$I$61,"핸드파레트",'예비 및 여유차량'!$J$55:$J$61,"2.5T") -> 0 | Y13: =COUNTIFS('예비 및 여유차량'!$B$55:$B$61,"B",'예비 및 여유차량'!$I$55:$I$61,"핸드리프트",'예비 및 여유차량'!$J$55:$J$61,"2.5T") -> 0 | Z13: =COUNTIFS('예비 및 여유차량'!$B$55:$B$61,"B",'예비 및 여유차량'!$I$55:$I$61,"<>핸드리프트",'예비 및 여유차량'!$I$55:$I$61,"<>핸드파레트",'예비 및 여유차량'!$I$55:$I$61,"<>입식",'예비 및 여유차량'!$I$55:$I$61,"<>좌식",'예비 및 여유차량'!$J$55:$J$61,"2.5T") -> 0
B14: 3.0T | C14: =COUNTIFS('예비 및 여유차량'!$B$5:$B$24,"O",'예비 및 여유차량'!$I$5:$I$24,"좌식",'예비 및 여유차량'!$J$5:$J$24,"3.0T") -> 2 | D14: =COUNTIFS('예비 및 여유차량'!$B$5:$B$24,"B",'예비 및 여유차량'!$I$5:$I$24,"좌식",'예비 및 여유차량'!$J$5:$J$24,"3.0T") -> 1 | E14: =COUNTIFS('예비 및 여유차량'!$B$5:$B$24,"B",'예비 및 여유차량'!$I$5:$I$24,"입식",'예비 및 여유차량'!$J$5:$J$24,"3.0T") -> 0 | F14: =COUNTIFS('예비 및 여유차량'!$B$5:$B$24,"B",'예비 및 여유차량'!$I$5:$I$24,"핸드파레트",'예비 및 여유차량'!$J$5:$J$24,"3.0T") -> 0 | G14: =COUNTIFS('예비 및 여유차량'!$B$5:$B$24,"B",'예비 및 여유차량'!$I$5:$I$24,"핸드리프트",'예비 및 여유차량'!$J$5:$J$24,"3.0T") -> 0 | H14: =COUNTIFS('예비 및 여유차량'!$B$5:$B$24,"B",'예비 및 여유차량'!$I$5:$I$24,"<>핸드리프트",'예비 및 여유차량'!$I$5:$I$24,"<>핸드파레트",'예비 및 여유차량'!$I$5:$I$24,"<>입식",'예비 및 여유차량'!$I$5:$I$24,"<>좌식",'예비 및 여유차량'!$J$5:$J$24,"3.0T") -> 0 | I14: =COUNTIFS('예비 및 여유차량'!B27:B30,"O",'예비 및 여유차량'!$I$27:$I$30,"좌식",'예비 및 여유차량'!$J$27:$J$30,"3.0T") -> 0 | J14: =COUNTIFS('예비 및 여유차량'!B27:B30,"B",'예비 및 여유차량'!$I$27:$I$30,"좌식",'예비 및 여유차량'!$J$27:$J$30,"3.0T") -> 1 | K14: =COUNTIFS('예비 및 여유차량'!B27:B30,"B",'예비 및 여유차량'!$I$27:$I$30,"입식",'예비 및 여유차량'!$J$27:$J$30,"3.0T") -> 0 | L14: =COUNTIFS('예비 및 여유차량'!B27:B30,"B",'예비 및 여유차량'!$I$27:$I$30,"핸드파레트",'예비 및 여유차량'!$J$27:$J$30,"3.0T") -> 0 | M14: =COUNTIFS('예비 및 여유차량'!A27:A30,"B",'예비 및 여유차량'!$I$27:$I$30,"핸드리프트",'예비 및 여유차량'!$J$27:$J$30,"3.0T") -> 0 | N14: =COUNTIFS('예비 및 여유차량'!A31:A34,"B",'예비 및 여유차량'!I31:I34,"<>핸드리프트",'예비 및 여유차량'!I31:I34,"<>핸드파레트",'예비 및 여유차량'!I31:I34,"<>입식",'예비 및 여유차량'!I31:I34,"<>좌식",'예비 및 여유차량'!J31:J34,"3.0T") -> 0 | O14: =COUNTIFS('예비 및 여유차량'!$B$34:$B$44,"O",'예비 및 여유차량'!$I$34:$I$44,"좌식",'예비 및 여유차량'!$J$34:$J$44,"3.0T") -> 1 | P14: =COUNTIFS('예비 및 여유차량'!$B$34:$B$44,"B",'예비 및 여유차량'!$I$34:$I$44,"좌식",'예비 및 여유차량'!$J$34:$J$44,"3.0T") -> 0 | Q14: =COUNTIFS('예비 및 여유차량'!$B$34:$B$44,"B",'예비 및 여유차량'!$I$34:$I$44,"입식",'예비 및 여유차량'!$J$34:$J$44,"3.0T") -> 0 | R14: =COUNTIFS('예비 및 여유차량'!$B$34:$B$44,"B",'예비 및 여유차량'!$I$34:$I$44,"핸드파레트",'예비 및 여유차량'!$J$34:$J$44,"3.0T") -> 0 | S14: =COUNTIFS('예비 및 여유차량'!$B$34:$B$44,"B",'예비 및 여유차량'!$I$34:$I$44,"핸드리프트",'예비 및 여유차량'!$J$34:$J$44,"3.0T") -> 0 | T14: =COUNTIFS('예비 및 여유차량'!$B$34:$B$44,"B",'예비 및 여유차량'!$I$34:$I$44,"<>핸드리프트",'예비 및 여유차량'!$I$34:$I$44,"<>핸드파레트",'예비 및 여유차량'!$I$34:$I$44,"<>입식",'예비 및 여유차량'!$I$34:$I$44,"<>좌식",'예비 및 여유차량'!$J$34:$J$44,"3.0T") -> 0 | U14: =COUNTIFS('예비 및 여유차량'!$B$55:$B$61,"O",'예비 및 여유차량'!$I$55:$I$61,"좌식",'예비 및 여유차량'!$J$55:$J$61,"3.0T") -> 0 | V14: =COUNTIFS('예비 및 여유차량'!$B$55:$B$61,"B",'예비 및 여유차량'!$I$55:$I$61,"좌식",'예비 및 여유차량'!$J$55:$J$61,"3.0T") -> 0 | W14: =COUNTIFS('예비 및 여유차량'!$B$55:$B$61,"B",'예비 및 여유차량'!$I$55:$I$61,"입식",'예비 및 여유차량'!$J$55:$J$61,"3.0T") -> 0 | X14: =COUNTIFS('예비 및 여유차량'!$B$55:$B$61,"B",'예비 및 여유차량'!$I$55:$I$61,"핸드파레트",'예비 및 여유차량'!$J$55:$J$61,"3.0T") -> 0 | Y14: =COUNTIFS('예비 및 여유차량'!$B$55:$B$61,"B",'예비 및 여유차량'!$I$55:$I$61,"핸드리프트",'예비 및 여유차량'!$J$55:$J$61,"3.0T") -> 0 | Z14: =COUNTIFS('예비 및 여유차량'!$B$55:$B$61,"B",'예비 및 여유차량'!$I$55:$I$61,"<>핸드리프트",'예비 및 여유차량'!$I$55:$I$61,"<>핸드파레트",'예비 및 여유차량'!$I$55:$I$61,"<>입식",'예비 및 여유차량'!$I$55:$I$61,"<>좌식",'예비 및 여유차량'!$J$55:$J$61,"3.0T") -> 0
B15: 3.5T | C15: =COUNTIFS('예비 및 여유차량'!$B$5:$B$24,"O",'예비 및 여유차량'!$I$5:$I$24,"좌식",'예비 및 여유차량'!$J$5:$J$24,"3.5T") -> 2 | D15: =COUNTIFS('예비 및 여유차량'!$B$5:$B$24,"B",'예비 및 여유차량'!$I$5:$I$24,"좌식",'예비 및 여유차량'!$J$5:$J$24,"3.5T") -> 0 | E15: =COUNTIFS('예비 및 여유차량'!$B$5:$B$24,"B",'예비 및 여유차량'!$I$5:$I$24,"입식",'예비 및 여유차량'!$J$5:$J$24,"3.5T") -> 0 | F15: =COUNTIFS('예비 및 여유차량'!$B$5:$B$24,"B",'예비 및 여유차량'!$I$5:$I$24,"핸드파레트",'예비 및 여유차량'!$J$5:$J$24,"3.5T") -> 0 | G15: =COUNTIFS('예비 및 여유차량'!$B$5:$B$24,"B",'예비 및 여유차량'!$I$5:$I$24,"핸드리프트",'예비 및 여유차량'!$J$5:$J$24,"3.5T") -> 0 | H15: =COUNTIFS('예비 및 여유차량'!$B$5:$B$24,"B",'예비 및 여유차량'!$I$5:$I$24,"<>핸드리프트",'예비 및 여유차량'!$I$5:$I$24,"<>핸드파레트",'예비 및 여유차량'!$I$5:$I$24,"<>입식",'예비 및 여유차량'!$I$5:$I$24,"<>좌식",'예비 및 여유차량'!$J$5:$J$24,"3.5T") -> 0 | I15: =COUNTIFS('예비 및 여유차량'!B27:B30,"O",'예비 및 여유차량'!$I$27:$I$30,"좌식",'예비 및 여유차량'!$J$27:$J$30,"3.5T") -> 0 | J15: =COUNTIFS('예비 및 여유차량'!B27:B30,"B",'예비 및 여유차량'!$I$27:$I$30,"좌식",'예비 및 여유차량'!$J$27:$J$30,"3.5T") -> 0 | K15: =COUNTIFS('예비 및 여유차량'!B27:B30,"B",'예비 및 여유차량'!$I$27:$I$30,"입식",'예비 및 여유차량'!$J$27:$J$30,"3.5T") -> 0 | L15: =COUNTIFS('예비 및 여유차량'!B27:B30,"B",'예비 및 여유차량'!$I$27:$I$30,"핸드파레트",'예비 및 여유차량'!$J$27:$J$30,"3.5T") -> 0 | M15: =COUNTIFS('예비 및 여유차량'!A27:A30,"B",'예비 및 여유차량'!$I$27:$I$30,"핸드리프트",'예비 및 여유차량'!$J$27:$J$30,"3.5T") -> 0 | N15: =COUNTIFS('예비 및 여유차량'!A32:A35,"B",'예비 및 여유차량'!I32:I35,"<>핸드리프트",'예비 및 여유차량'!I32:I35,"<>핸드파레트",'예비 및 여유차량'!I32:I35,"<>입식",'예비 및 여유차량'!I32:I35,"<>좌식",'예비 및 여유차량'!J32:J35,"3.5T") -> 0 | O15: =COUNTIFS('예비 및 여유차량'!$B$34:$B$44,"O",'예비 및 여유차량'!$I$34:$I$44,"좌식",'예비 및 여유차량'!$J$34:$J$44,"3.5T") -> 0 | P15: =COUNTIFS('예비 및 여유차량'!$B$34:$B$44,"B",'예비 및 여유차량'!$I$34:$I$44,"좌식",'예비 및 여유차량'!$J$34:$J$44,"3.5T") -> 0 | Q15: =COUNTIFS('예비 및 여유차량'!$B$34:$B$44,"B",'예비 및 여유차량'!$I$34:$I$44,"입식",'예비 및 여유차량'!$J$34:$J$44,"3.5T") -> 0 | R15: =COUNTIFS('예비 및 여유차량'!$B$34:$B$44,"B",'예비 및 여유차량'!$I$34:$I$44,"핸드파레트",'예비 및 여유차량'!$J$34:$J$44,"3.5T") -> 0 | S15: =COUNTIFS('예비 및 여유차량'!$B$34:$B$44,"B",'예비 및 여유차량'!$I$34:$I$44,"핸드리프트",'예비 및 여유차량'!$J$34:$J$44,"3.5T") -> 0 | T15: =COUNTIFS('예비 및 여유차량'!$B$34:$B$44,"B",'예비 및 여유차량'!$I$34:$I$44,"<>핸드리프트",'예비 및 여유차량'!$I$34:$I$44,"<>핸드파레트",'예비 및 여유차량'!$I$34:$I$44,"<>입식",'예비 및 여유차량'!$I$34:$I$44,"<>좌식",'예비 및 여유차량'!$J$34:$J$44,"3.5T") -> 0 | U15: =COUNTIFS('예비 및 여유차량'!$B$55:$B$61,"O",'예비 및 여유차량'!$I$55:$I$61,"좌식",'예비 및 여유차량'!$J$55:$J$61,"3.5T") -> 0 | V15: =COUNTIFS('예비 및 여유차량'!$B$55:$B$61,"B",'예비 및 여유차량'!$I$55:$I$61,"좌식",'예비 및 여유차량'!$J$55:$J$61,"3.5T") -> 0 | W15: =COUNTIFS('예비 및 여유차량'!$B$55:$B$61,"B",'예비 및 여유차량'!$I$55:$I$61,"입식",'예비 및 여유차량'!$J$55:$J$61,"3.5T") -> 0 | X15: =COUNTIFS('예비 및 여유차량'!$B$55:$B$61,"B",'예비 및 여유차량'!$I$55:$I$61,"핸드파레트",'예비 및 여유차량'!$J$55:$J$61,"3.5T") -> 0 | Y15: =COUNTIFS('예비 및 여유차량'!$B$55:$B$61,"B",'예비 및 여유차량'!$I$55:$I$61,"핸드리프트",'예비 및 여유차량'!$J$55:$J$61,"3.5T") -> 0 | Z15: =COUNTIFS('예비 및 여유차량'!$B$55:$B$61,"B",'예비 및 여유차량'!$I$55:$I$61,"<>핸드리프트",'예비 및 여유차량'!$I$55:$I$61,"<>핸드파레트",'예비 및 여유차량'!$I$55:$I$61,"<>입식",'예비 및 여유차량'!$I$55:$I$61,"<>좌식",'예비 및 여유차량'!$J$55:$J$61,"3.5T") -> 0
B16: 4.0T | C16: =COUNTIFS('예비 및 여유차량'!$B$5:$B$24,"O",'예비 및 여유차량'!$I$5:$I$24,"좌식",'예비 및 여유차량'!$J$5:$J$24,"4.0T") -> 1 | D16: =COUNTIFS('예비 및 여유차량'!$B$5:$B$24,"B",'예비 및 여유차량'!$I$5:$I$24,"좌식",'예비 및 여유차량'!$J$5:$J$24,"4.0T") -> 0 | E16: =COUNTIFS('예비 및 여유차량'!$B$5:$B$24,"B",'예비 및 여유차량'!$I$5:$I$24,"입식",'예비 및 여유차량'!$J$5:$J$24,"4.0T") -> 0 | F16: =COUNTIFS('예비 및 여유차량'!$B$5:$B$24,"B",'예비 및 여유차량'!$I$5:$I$24,"핸드파레트",'예비 및 여유차량'!$J$5:$J$24,"4.0T") -> 0 | G16: =COUNTIFS('예비 및 여유차량'!$B$5:$B$24,"B",'예비 및 여유차량'!$I$5:$I$24,"핸드리프트",'예비 및 여유차량'!$J$5:$J$24,"4.0T") -> 0 | H16: =COUNTIFS('예비 및 여유차량'!$B$5:$B$24,"B",'예비 및 여유차량'!$I$5:$I$24,"<>핸드리프트",'예비 및 여유차량'!$I$5:$I$24,"<>핸드파레트",'예비 및 여유차량'!$I$5:$I$24,"<>입식",'예비 및 여유차량'!$I$5:$I$24,"<>좌식",'예비 및 여유차량'!$J$5:$J$24,"4.0T") -> 0 | I16: =COUNTIFS('예비 및 여유차량'!B27:B30,"O",'예비 및 여유차량'!$I$27:$I$30,"좌식",'예비 및 여유차량'!$J$27:$J$30,"4.0T") -> 0 | J16: =COUNTIFS('예비 및 여유차량'!B27:B30,"B",'예비 및 여유차량'!$I$27:$I$30,"좌식",'예비 및 여유차량'!$J$27:$J$30,"4.0T") -> 0 | K16: =COUNTIFS('예비 및 여유차량'!B27:B30,"B",'예비 및 여유차량'!$I$27:$I$30,"입식",'예비 및 여유차량'!$J$27:$J$30,"4.0T") -> 0 | L16: =COUNTIFS('예비 및 여유차량'!B27:B30,"B",'예비 및 여유차량'!$I$27:$I$30,"핸드파레트",'예비 및 여유차량'!$J$27:$J$30,"4.0T") -> 0 | M16: =COUNTIFS('예비 및 여유차량'!A27:A30,"B",'예비 및 여유차량'!$I$27:$I$30,"핸드리프트",'예비 및 여유차량'!$J$27:$J$30,"4.0T") -> 0 | N16: =COUNTIFS('예비 및 여유차량'!A33:A35,"B",'예비 및 여유차량'!I33:I35,"<>핸드리프트",'예비 및 여유차량'!I33:I35,"<>핸드파레트",'예비 및 여유차량'!I33:I35,"<>입식",'예비 및 여유차량'!I33:I35,"<>좌식",'예비 및 여유차량'!J33:J35,"4.0T") -> 0 | O16: =COUNTIFS('예비 및 여유차량'!$B$34:$B$44,"O",'예비 및 여유차량'!$I$34:$I$44,"좌식",'예비 및 여유차량'!$J$34:$J$44,"4.0T") -> 0 | P16: =COUNTIFS('예비 및 여유차량'!$B$34:$B$44,"B",'예비 및 여유차량'!$I$34:$I$44,"좌식",'예비 및 여유차량'!$J$34:$J$44,"4.0T") -> 0 | Q16: =COUNTIFS('예비 및 여유차량'!$B$34:$B$44,"B",'예비 및 여유차량'!$I$34:$I$44,"입식",'예비 및 여유차량'!$J$34:$J$44,"4.0T") -> 0 | R16: =COUNTIFS('예비 및 여유차량'!$B$34:$B$44,"B",'예비 및 여유차량'!$I$34:$I$44,"핸드파레트",'예비 및 여유차량'!$J$34:$J$44,"4.0T") -> 0 | S16: =COUNTIFS('예비 및 여유차량'!$B$34:$B$44,"B",'예비 및 여유차량'!$I$34:$I$44,"핸드리프트",'예비 및 여유차량'!$J$34:$J$44,"4.0T") -> 0 | T16: =COUNTIFS('예비 및 여유차량'!$B$34:$B$44,"B",'예비 및 여유차량'!$I$34:$I$44,"<>핸드리프트",'예비 및 여유차량'!$I$34:$I$44,"<>핸드파레트",'예비 및 여유차량'!$I$34:$I$44,"<>입식",'예비 및 여유차량'!$I$34:$I$44,"<>좌식",'예비 및 여유차량'!$J$34:$J$44,"4.0T") -> 0 | U16: =COUNTIFS('예비 및 여유차량'!$B$55:$B$61,"O",'예비 및 여유차량'!$I$55:$I$61,"좌식",'예비 및 여유차량'!$J$55:$J$61,"4.0T") -> 0 | V16: =COUNTIFS('예비 및 여유차량'!$B$55:$B$61,"B",'예비 및 여유차량'!$I$55:$I$61,"좌식",'예비 및 여유차량'!$J$55:$J$61,"4.0T") -> 0 | W16: =COUNTIFS('예비 및 여유차량'!$B$55:$B$61,"B",'예비 및 여유차량'!$I$55:$I$61,"입식",'예비 및 여유차량'!$J$55:$J$61,"4.0T") -> 0 | X16: =COUNTIFS('예비 및 여유차량'!$B$55:$B$61,"B",'예비 및 여유차량'!$I$55:$I$61,"핸드파레트",'예비 및 여유차량'!$J$55:$J$61,"4.0T") -> 0 | Y16: =COUNTIFS('예비 및 여유차량'!$B$55:$B$61,"B",'예비 및 여유차량'!$I$55:$I$61,"핸드리프트",'예비 및 여유차량'!$J$55:$J$61,"4.0T") -> 0 | Z16: =COUNTIFS('예비 및 여유차량'!$B$55:$B$61,"B",'예비 및 여유차량'!$I$55:$I$61,"<>핸드리프트",'예비 및 여유차량'!$I$55:$I$61,"<>핸드파레트",'예비 및 여유차량'!$I$55:$I$61,"<>입식",'예비 및 여유차량'!$I$55:$I$61,"<>좌식",'예비 및 여유차량'!$J$55:$J$61,"4.0T") -> 0
B17: 4.5T | C17: =COUNTIFS('예비 및 여유차량'!$B$5:$B$24,"O",'예비 및 여유차량'!$I$5:$I$24,"좌식",'예비 및 여유차량'!$J$5:$J$24,"4.5T") -> 3 | D17: =COUNTIFS('예비 및 여유차량'!$B$5:$B$24,"B",'예비 및 여유차량'!$I$5:$I$24,"좌식",'예비 및 여유차량'!$J$5:$J$24,"4.5T") -> 0 | E17: =COUNTIFS('예비 및 여유차량'!$B$5:$B$24,"B",'예비 및 여유차량'!$I$5:$I$24,"입식",'예비 및 여유차량'!$J$5:$J$24,"4.5T") -> 0 | F17: =COUNTIFS('예비 및 여유차량'!$B$5:$B$24,"B",'예비 및 여유차량'!$I$5:$I$24,"핸드파레트",'예비 및 여유차량'!$J$5:$J$24,"4.5T") -> 0 | G17: =COUNTIFS('예비 및 여유차량'!$B$5:$B$24,"B",'예비 및 여유차량'!$I$5:$I$24,"핸드리프트",'예비 및 여유차량'!$J$5:$J$24,"4.5T") -> 0 | H17: =COUNTIFS('예비 및 여유차량'!$B$5:$B$24,"B",'예비 및 여유차량'!$I$5:$I$24,"<>핸드리프트",'예비 및 여유차량'!$I$5:$I$24,"<>핸드파레트",'예비 및 여유차량'!$I$5:$I$24,"<>입식",'예비 및 여유차량'!$I$5:$I$24,"<>좌식",'예비 및 여유차량'!$J$5:$J$24,"4.5T") -> 0 | I17: =COUNTIFS('예비 및 여유차량'!B27:B30,"O",'예비 및 여유차량'!$I$27:$I$30,"좌식",'예비 및 여유차량'!$J$27:$J$30,"4.5T") -> 0 | J17: =COUNTIFS('예비 및 여유차량'!B27:B30,"B",'예비 및 여유차량'!$I$27:$I$30,"좌식",'예비 및 여유차량'!$J$27:$J$30,"4.5T") -> 0 | K17: =COUNTIFS('예비 및 여유차량'!B27:B30,"B",'예비 및 여유차량'!$I$27:$I$30,"입식",'예비 및 여유차량'!$J$27:$J$30,"4.5T") -> 0 | L17: =COUNTIFS('예비 및 여유차량'!B27:B30,"B",'예비 및 여유차량'!$I$27:$I$30,"핸드파레트",'예비 및 여유차량'!$J$27:$J$30,"4.5T") -> 0 | M17: =COUNTIFS('예비 및 여유차량'!A27:A30,"B",'예비 및 여유차량'!$I$27:$I$30,"핸드리프트",'예비 및 여유차량'!$J$27:$J$30,"4.5T") -> 0 | N17: =COUNTIFS('예비 및 여유차량'!A34:A37,"B",'예비 및 여유차량'!I34:I37,"<>핸드리프트",'예비 및 여유차량'!I34:I37,"<>핸드파레트",'예비 및 여유차량'!I34:I37,"<>입식",'예비 및 여유차량'!I34:I37,"<>좌식",'예비 및 여유차량'!J34:J37,"4.5T") -> 0 | O17: =COUNTIFS('예비 및 여유차량'!$B$34:$B$44,"O",'예비 및 여유차량'!$I$34:$I$44,"좌식",'예비 및 여유차량'!$J$34:$J$44,"4.5T") -> 2 | P17: =COUNTIFS('예비 및 여유차량'!$B$34:$B$44,"B",'예비 및 여유차량'!$I$34:$I$44,"좌식",'예비 및 여유차량'!$J$34:$J$44,"4.5T") -> 0 | Q17: =COUNTIFS('예비 및 여유차량'!$B$34:$B$44,"B",'예비 및 여유차량'!$I$34:$I$44,"입식",'예비 및 여유차량'!$J$34:$J$44,"4.5T") -> 0 | R17: =COUNTIFS('예비 및 여유차량'!$B$34:$B$44,"B",'예비 및 여유차량'!$I$34:$I$44,"핸드파레트",'예비 및 여유차량'!$J$34:$J$44,"4.5T") -> 0 | S17: =COUNTIFS('예비 및 여유차량'!$B$34:$B$44,"B",'예비 및 여유차량'!$I$34:$I$44,"핸드리프트",'예비 및 여유차량'!$J$34:$J$44,"4.5T") -> 0 | T17: =COUNTIFS('예비 및 여유차량'!$B$34:$B$44,"B",'예비 및 여유차량'!$I$34:$I$44,"<>핸드리프트",'예비 및 여유차량'!$I$34:$I$44,"<>핸드파레트",'예비 및 여유차량'!$I$34:$I$44,"<>입식",'예비 및 여유차량'!$I$34:$I$44,"<>좌식",'예비 및 여유차량'!$J$34:$J$44,"4.5T") -> 0 | U17: =COUNTIFS('예비 및 여유차량'!$B$55:$B$61,"O",'예비 및 여유차량'!$I$55:$I$61,"좌식",'예비 및 여유차량'!$J$55:$J$61,"4.5T") -> 0 | V17: =COUNTIFS('예비 및 여유차량'!$B$55:$B$61,"B",'예비 및 여유차량'!$I$55:$I$61,"좌식",'예비 및 여유차량'!$J$55:$J$61,"4.5T") -> 0 | W17: =COUNTIFS('예비 및 여유차량'!$B$55:$B$61,"B",'예비 및 여유차량'!$I$55:$I$61,"입식",'예비 및 여유차량'!$J$55:$J$61,"4.5T") -> 0 | X17: =COUNTIFS('예비 및 여유차량'!$B$55:$B$61,"B",'예비 및 여유차량'!$I$55:$I$61,"핸드파레트",'예비 및 여유차량'!$J$55:$J$61,"4.5T") -> 0 | Y17: =COUNTIFS('예비 및 여유차량'!$B$55:$B$61,"B",'예비 및 여유차량'!$I$55:$I$61,"핸드리프트",'예비 및 여유차량'!$J$55:$J$61,"4.5T") -> 0 | Z17: =COUNTIFS('예비 및 여유차량'!$B$55:$B$61,"B",'예비 및 여유차량'!$I$55:$I$61,"<>핸드리프트",'예비 및 여유차량'!$I$55:$I$61,"<>핸드파레트",'예비 및 여유차량'!$I$55:$I$61,"<>입식",'예비 및 여유차량'!$I$55:$I$61,"<>좌식",'예비 및 여유차량'!$J$55:$J$61,"4.5T") -> 0
B18: 5.0T | C18: =COUNTIFS('예비 및 여유차량'!$B$5:$B$24,"O",'예비 및 여유차량'!$I$5:$I$24,"좌식",'예비 및 여유차량'!$J$5:$J$24,"5.0T") -> 0 | D18: =COUNTIFS('예비 및 여유차량'!$B$5:$B$24,"B",'예비 및 여유차량'!$I$5:$I$24,"좌식",'예비 및 여유차량'!$J$5:$J$24,"5.0T") -> 0 | E18: =COUNTIFS('예비 및 여유차량'!$B$5:$B$24,"B",'예비 및 여유차량'!$I$5:$I$24,"입식",'예비 및 여유차량'!$J$5:$J$24,"5.0T") -> 0 | F18: =COUNTIFS('예비 및 여유차량'!$B$5:$B$24,"B",'예비 및 여유차량'!$I$5:$I$24,"핸드파레트",'예비 및 여유차량'!$J$5:$J$24,"5.0T") -> 0 | G18: =COUNTIFS('예비 및 여유차량'!$B$5:$B$24,"B",'예비 및 여유차량'!$I$5:$I$24,"핸드리프트",'예비 및 여유차량'!$J$5:$J$24,"5.0T") -> 0 | H18: =COUNTIFS('예비 및 여유차량'!$B$5:$B$24,"B",'예비 및 여유차량'!$I$5:$I$24,"<>핸드리프트",'예비 및 여유차량'!$I$5:$I$24,"<>핸드파레트",'예비 및 여유차량'!$I$5:$I$24,"<>입식",'예비 및 여유차량'!$I$5:$I$24,"<>좌식",'예비 및 여유차량'!$J$5:$J$24,"5.0T") -> 0 | I18: =COUNTIFS('예비 및 여유차량'!B27:B30,"O",'예비 및 여유차량'!$I$27:$I$30,"좌식",'예비 및 여유차량'!$J$27:$J$30,"5.0T") -> 0 | J18: =COUNTIFS('예비 및 여유차량'!B27:B30,"B",'예비 및 여유차량'!$I$27:$I$30,"좌식",'예비 및 여유차량'!$J$27:$J$30,"5.0T") -> 0 | K18: =COUNTIFS('예비 및 여유차량'!B27:B30,"B",'예비 및 여유차량'!$I$27:$I$30,"입식",'예비 및 여유차량'!$J$27:$J$30,"5.0T") -> 0 | L18: =COUNTIFS('예비 및 여유차량'!B27:B30,"B",'예비 및 여유차량'!$I$27:$I$30,"핸드파레트",'예비 및 여유차량'!$J$27:$J$30,"5.0T") -> 0 | M18: =COUNTIFS('예비 및 여유차량'!A27:A30,"B",'예비 및 여유차량'!$I$27:$I$30,"핸드리프트",'예비 및 여유차량'!$J$27:$J$30,"5.0T") -> 0 | N18: =COUNTIFS('예비 및 여유차량'!A35:A38,"B",'예비 및 여유차량'!I35:I38,"<>핸드리프트",'예비 및 여유차량'!I35:I38,"<>핸드파레트",'예비 및 여유차량'!I35:I38,"<>입식",'예비 및 여유차량'!I35:I38,"<>좌식",'예비 및 여유차량'!J35:J38,"5.0T") -> 0 | O18: =COUNTIFS('예비 및 여유차량'!$B$34:$B$44,"O",'예비 및 여유차량'!$I$34:$I$44,"좌식",'예비 및 여유차량'!$J$34:$J$44,"5.0T") -> 1 | P18: =COUNTIFS('예비 및 여유차량'!$B$34:$B$44,"B",'예비 및 여유차량'!$I$34:$I$44,"좌식",'예비 및 여유차량'!$J$34:$J$44,"5.0T") -> 1 | Q18: =COUNTIFS('예비 및 여유차량'!$B$34:$B$44,"B",'예비 및 여유차량'!$I$34:$I$44,"입식",'예비 및 여유차량'!$J$34:$J$44,"5.0T") -> 0 | R18: =COUNTIFS('예비 및 여유차량'!$B$34:$B$44,"B",'예비 및 여유차량'!$I$34:$I$44,"핸드파레트",'예비 및 여유차량'!$J$34:$J$44,"5.0T") -> 0 | S18: =COUNTIFS('예비 및 여유차량'!$B$34:$B$44,"B",'예비 및 여유차량'!$I$34:$I$44,"핸드리프트",'예비 및 여유차량'!$J$34:$J$44,"5.0T") -> 0 | T18: =COUNTIFS('예비 및 여유차량'!$B$34:$B$44,"B",'예비 및 여유차량'!$I$34:$I$44,"<>핸드리프트",'예비 및 여유차량'!$I$34:$I$44,"<>핸드파레트",'예비 및 여유차량'!$I$34:$I$44,"<>입식",'예비 및 여유차량'!$I$34:$I$44,"<>좌식",'예비 및 여유차량'!$J$34:$J$44,"5.0T") -> 0 | U18: =COUNTIFS('예비 및 여유차량'!$B$55:$B$61,"O",'예비 및 여유차량'!$I$55:$I$61,"좌식",'예비 및 여유차량'!$J$55:$J$61,"5.0T") -> 0 | V18: =COUNTIFS('예비 및 여유차량'!$B$55:$B$61,"B",'예비 및 여유차량'!$I$55:$I$61,"좌식",'예비 및 여유차량'!$J$55:$J$61,"5.0T") -> 0 | W18: =COUNTIFS('예비 및 여유차량'!$B$55:$B$61,"B",'예비 및 여유차량'!$I$55:$I$61,"입식",'예비 및 여유차량'!$J$55:$J$61,"5.0T") -> 0 | X18: =COUNTIFS('예비 및 여유차량'!$B$55:$B$61,"B",'예비 및 여유차량'!$I$55:$I$61,"핸드파레트",'예비 및 여유차량'!$J$55:$J$61,"5.0T") -> 0 | Y18: =COUNTIFS('예비 및 여유차량'!$B$55:$B$61,"B",'예비 및 여유차량'!$I$55:$I$61,"핸드리프트",'예비 및 여유차량'!$J$55:$J$61,"5.0T") -> 0 | Z18: =COUNTIFS('예비 및 여유차량'!$B$55:$B$61,"B",'예비 및 여유차량'!$I$55:$I$61,"<>핸드리프트",'예비 및 여유차량'!$I$55:$I$61,"<>핸드파레트",'예비 및 여유차량'!$I$55:$I$61,"<>입식",'예비 및 여유차량'!$I$55:$I$61,"<>좌식",'예비 및 여유차량'!$J$55:$J$61,"5.0T") -> 0
B19: 7.0T | C19: =COUNTIFS('예비 및 여유차량'!$B$5:$B$24,"O",'예비 및 여유차량'!$I$5:$I$24,"좌식",'예비 및 여유차량'!$J$5:$J$24,"7.0T") -> 0 | D19: =COUNTIFS('예비 및 여유차량'!$B$5:$B$24,"B",'예비 및 여유차량'!$I$5:$I$24,"좌식",'예비 및 여유차량'!$J$5:$J$24,"7.0T") -> 0 | E19: =COUNTIFS('예비 및 여유차량'!$B$5:$B$24,"B",'예비 및 여유차량'!$I$5:$I$24,"입식",'예비 및 여유차량'!$J$5:$J$24,"7.0T") -> 0 | F19: =COUNTIFS('예비 및 여유차량'!$B$5:$B$24,"B",'예비 및 여유차량'!$I$5:$I$24,"핸드파레트",'예비 및 여유차량'!$J$5:$J$24,"7.0T") -> 0 | G19: =COUNTIFS('예비 및 여유차량'!$B$5:$B$24,"B",'예비 및 여유차량'!$I$5:$I$24,"핸드리프트",'예비 및 여유차량'!$J$5:$J$24,"7.0T") -> 0 | H19: =COUNTIFS('예비 및 여유차량'!$B$5:$B$24,"B",'예비 및 여유차량'!$I$5:$I$24,"<>핸드리프트",'예비 및 여유차량'!$I$5:$I$24,"<>핸드파레트",'예비 및 여유차량'!$I$5:$I$24,"<>입식",'예비 및 여유차량'!$I$5:$I$24,"<>좌식",'예비 및 여유차량'!$J$5:$J$24,"7.0T") -> 2 | I19: =COUNTIFS('예비 및 여유차량'!B27:B30,"O",'예비 및 여유차량'!$I$27:$I$30,"좌식",'예비 및 여유차량'!$J$27:$J$30,"7.0T") -> 1 | J19: =COUNTIFS('예비 및 여유차량'!B27:B30,"B",'예비 및 여유차량'!$I$27:$I$30,"좌식",'예비 및 여유차량'!$J$27:$J$30,"7.0T") -> 0 | K19: =COUNTIFS('예비 및 여유차량'!B27:B30,"B",'예비 및 여유차량'!$I$27:$I$30,"입식",'예비 및 여유차량'!$J$27:$J$30,"7.0T") -> 0 | L19: =COUNTIFS('예비 및 여유차량'!B27:B30,"B",'예비 및 여유차량'!$I$27:$I$30,"핸드파레트",'예비 및 여유차량'!$J$27:$J$30,"7.0T") -> 0 | M19: =COUNTIFS('예비 및 여유차량'!A27:A30,"B",'예비 및 여유차량'!$I$27:$I$30,"핸드리프트",'예비 및 여유차량'!$J$27:$J$30,"7.0T") -> 0 | N19: =COUNTIFS('예비 및 여유차량'!A37:A39,"B",'예비 및 여유차량'!I37:I39,"<>핸드리프트",'예비 및 여유차량'!I37:I39,"<>핸드파레트",'예비 및 여유차량'!I37:I39,"<>입식",'예비 및 여유차량'!I37:I39,"<>좌식",'예비 및 여유차량'!J37:J39,"7.0T") -> 0 | O19: =COUNTIFS('예비 및 여유차량'!$B$34:$B$44,"O",'예비 및 여유차량'!$I$34:$I$44,"좌식",'예비 및 여유차량'!$J$34:$J$44,"7.0T") -> 0 | P19: =COUNTIFS('예비 및 여유차량'!$B$34:$B$44,"B",'예비 및 여유차량'!$I$34:$I$44,"좌식",'예비 및 여유차량'!$J$34:$J$44,"7.0T") -> 0 | Q19: =COUNTIFS('예비 및 여유차량'!$B$34:$B$44,"B",'예비 및 여유차량'!$I$34:$I$44,"입식",'예비 및 여유차량'!$J$34:$J$44,"7.0T") -> 0 | R19: =COUNTIFS('예비 및 여유차량'!$B$34:$B$44,"B",'예비 및 여유차량'!$I$34:$I$44,"핸드파레트",'예비 및 여유차량'!$J$34:$J$44,"7.0T") -> 0 | S19: =COUNTIFS('예비 및 여유차량'!$B$34:$B$44,"B",'예비 및 여유차량'!$I$34:$I$44,"핸드리프트",'예비 및 여유차량'!$J$34:$J$44,"7.0T") -> 0 | T19: =COUNTIFS('예비 및 여유차량'!$B$34:$B$44,"B",'예비 및 여유차량'!$I$34:$I$44,"<>핸드리프트",'예비 및 여유차량'!$I$34:$I$44,"<>핸드파레트",'예비 및 여유차량'!$I$34:$I$44,"<>입식",'예비 및 여유차량'!$I$34:$I$44,"<>좌식",'예비 및 여유차량'!$J$34:$J$44,"7.0T") -> 1 | U19: =COUNTIFS('예비 및 여유차량'!$B$55:$B$61,"O",'예비 및 여유차량'!$I$55:$I$61,"좌식",'예비 및 여유차량'!$J$55:$J$61,"7.0T") -> 0 | V19: =COUNTIFS('예비 및 여유차량'!$B$55:$B$61,"B",'예비 및 여유차량'!$I$55:$I$61,"좌식",'예비 및 여유차량'!$J$55:$J$61,"7.0T") -> 0 | W19: =COUNTIFS('예비 및 여유차량'!$B$55:$B$61,"B",'예비 및 여유차량'!$I$55:$I$61,"입식",'예비 및 여유차량'!$J$55:$J$61,"7.0T") -> 0 | X19: =COUNTIFS('예비 및 여유차량'!$B$55:$B$61,"B",'예비 및 여유차량'!$I$55:$I$61,"핸드파레트",'예비 및 여유차량'!$J$55:$J$61,"7.0T") -> 0 | Y19: =COUNTIFS('예비 및 여유차량'!$B$55:$B$61,"B",'예비 및 여유차량'!$I$55:$I$61,"핸드리프트",'예비 및 여유차량'!$J$55:$J$61,"7.0T") -> 0 | Z19: =COUNTIFS('예비 및 여유차량'!$B$55:$B$61,"B",'예비 및 여유차량'!$I$55:$I$61,"<>핸드리프트",'예비 및 여유차량'!$I$55:$I$61,"<>핸드파레트",'예비 및 여유차량'!$I$55:$I$61,"<>입식",'예비 및 여유차량'!$I$55:$I$61,"<>좌식",'예비 및 여유차량'!$J$55:$J$61,"7.0T") -> 0
B20: 16T | C20: =COUNTIFS('예비 및 여유차량'!$B$5:$B$24,"O",'예비 및 여유차량'!$I$5:$I$24,"좌식",'예비 및 여유차량'!$J$5:$J$24,"16T") -> 0 | D20: =COUNTIFS('예비 및 여유차량'!$B$5:$B$24,"B",'예비 및 여유차량'!$I$5:$I$24,"좌식",'예비 및 여유차량'!$J$5:$J$24,"16T") -> 0 | E20: =COUNTIFS('예비 및 여유차량'!$B$5:$B$24,"B",'예비 및 여유차량'!$I$5:$I$24,"입식",'예비 및 여유차량'!$J$5:$J$24,"16T") -> 0 | F20: =COUNTIFS('예비 및 여유차량'!$B$5:$B$24,"B",'예비 및 여유차량'!$I$5:$I$24,"핸드파레트",'예비 및 여유차량'!$J$5:$J$24,"16T") -> 0 | G20: =COUNTIFS('예비 및 여유차량'!$B$5:$B$24,"B",'예비 및 여유차량'!$I$5:$I$24,"핸드리프트",'예비 및 여유차량'!$J$5:$J$24,"16T") -> 0 | H20: =COUNTIFS('예비 및 여유차량'!$B$5:$B$24,"B",'예비 및 여유차량'!$I$5:$I$24,"<>핸드리프트",'예비 및 여유차량'!$I$5:$I$24,"<>핸드파레트",'예비 및 여유차량'!$I$5:$I$24,"<>입식",'예비 및 여유차량'!$I$5:$I$24,"<>좌식",'예비 및 여유차량'!$J$5:$J$24,"16T") -> 0 | I20: =COUNTIFS('예비 및 여유차량'!B28:B31,"O",'예비 및 여유차량'!$I$27:$I$30,"좌식",'예비 및 여유차량'!$J$27:$J$30,"16T") -> 0 | J20: =COUNTIFS('예비 및 여유차량'!B28:B31,"B",'예비 및 여유차량'!$I$27:$I$30,"좌식",'예비 및 여유차량'!$J$27:$J$30,"16T") -> 0 | K20: =COUNTIFS('예비 및 여유차량'!B28:B31,"B",'예비 및 여유차량'!$I$27:$I$30,"입식",'예비 및 여유차량'!$J$27:$J$30,"16T") -> 0 | L20: =COUNTIFS('예비 및 여유차량'!B28:B31,"B",'예비 및 여유차량'!$I$27:$I$30,"핸드파레트",'예비 및 여유차량'!$J$27:$J$30,"16T") -> 0 | M20: =COUNTIFS('예비 및 여유차량'!A28:A31,"B",'예비 및 여유차량'!$I$27:$I$30,"핸드리프트",'예비 및 여유차량'!$J$27:$J$30,"16T") -> 0 | N20: =COUNTIFS('예비 및 여유차량'!A37:A40,"B",'예비 및 여유차량'!I37:I40,"<>핸드리프트",'예비 및 여유차량'!I37:I40,"<>핸드파레트",'예비 및 여유차량'!I37:I40,"<>입식",'예비 및 여유차량'!I37:I40,"<>좌식",'예비 및 여유차량'!J37:J40,"16T") -> 0 | O20: =COUNTIFS('예비 및 여유차량'!$B$34:$B$44,"O",'예비 및 여유차량'!$I$34:$I$44,"좌식",'예비 및 여유차량'!$J$34:$J$44,"16T") -> 1 | P20: =COUNTIFS('예비 및 여유차량'!$B$34:$B$44,"B",'예비 및 여유차량'!$I$34:$I$44,"좌식",'예비 및 여유차량'!$J$34:$J$44,"16T") -> 0 | Q20: =COUNTIFS('예비 및 여유차량'!$B$34:$B$44,"B",'예비 및 여유차량'!$I$34:$I$44,"입식",'예비 및 여유차량'!$J$34:$J$44,"16T") -> 0 | R20: =COUNTIFS('예비 및 여유차량'!$B$34:$B$44,"B",'예비 및 여유차량'!$I$34:$I$44,"핸드파레트",'예비 및 여유차량'!$J$34:$J$44,"16T") -> 0 | S20: =COUNTIFS('예비 및 여유차량'!$B$34:$B$44,"B",'예비 및 여유차량'!$I$34:$I$44,"핸드리프트",'예비 및 여유차량'!$J$34:$J$44,"16T") -> 0 | T20: =COUNTIFS('예비 및 여유차량'!$B$34:$B$44,"B",'예비 및 여유차량'!$I$34:$I$44,"<>핸드리프트",'예비 및 여유차량'!$I$34:$I$44,"<>핸드파레트",'예비 및 여유차량'!$I$34:$I$44,"<>입식",'예비 및 여유차량'!$I$34:$I$44,"<>좌식",'예비 및 여유차량'!$J$34:$J$44,"16T") -> 0 | U20: =COUNTIFS('예비 및 여유차량'!$B$55:$B$61,"O",'예비 및 여유차량'!$I$55:$I$61,"좌식",'예비 및 여유차량'!$J$55:$J$61,"16T") -> 0 | V20: =COUNTIFS('예비 및 여유차량'!$B$55:$B$61,"B",'예비 및 여유차량'!$I$55:$I$61,"좌식",'예비 및 여유차량'!$J$55:$J$61,"16T") -> 0 | W20: =COUNTIFS('예비 및 여유차량'!$B$55:$B$61,"B",'예비 및 여유차량'!$I$55:$I$61,"입식",'예비 및 여유차량'!$J$55:$J$61,"16T") -> 0 | X20: =COUNTIFS('예비 및 여유차량'!$B$55:$B$61,"B",'예비 및 여유차량'!$I$55:$I$61,"핸드파레트",'예비 및 여유차량'!$J$55:$J$61,"16T") -> 0 | Y20: =COUNTIFS('예비 및 여유차량'!$B$55:$B$61,"B",'예비 및 여유차량'!$I$55:$I$61,"핸드리프트",'예비 및 여유차량'!$J$55:$J$61,"16T") -> 0 | Z20: =COUNTIFS('예비 및 여유차량'!$B$55:$B$61,"B",'예비 및 여유차량'!$I$55:$I$61,"<>핸드리프트",'예비 및 여유차량'!$I$55:$I$61,"<>핸드파레트",'예비 및 여유차량'!$I$55:$I$61,"<>입식",'예비 및 여유차량'!$I$55:$I$61,"<>좌식",'예비 및 여유차량'!$J$55:$J$61,"16T") -> 0
B21: 합계 | C21: =SUM(C10:C20) -> 8 | D21: =SUM(D10:D20) -> 5 | E21: =SUM(E10:E20) -> 0 | F21: =SUM(F10:F20) -> 1 | G21: =SUM(G10:G20) -> 2 | H21: =SUM(H10:H20) -> 4 | I21: =SUM(I10:I20) -> 2 | J21: =SUM(J10:J20) -> 2 | ... Z21: =SUM(Z10:Z20) -> 0
B24: Ton | C24: Year
